Workbook
Name ReleaseList: Lists!$G$2:$G$100

Sheet README
B1: EINT MuleSoft Backlog Tracker — How This Works
B3: Replaces: MuleSoft Team - Planning.xlsx and Requirements Traceability Matrix - EINT Mulesoft 2026.xlsx
B5: The golden rule: every field has exactly one home.
B6: Each requirement is one row, tracked by its Requirement ID across every tab below. Each field (Priority, Sprint, Dependencies, Release, etc.) is only ever typed into ONE tab — the tab owned by the role responsible for it. Every other tab shows that same field automatically, pulled live from wherever it was entered. If you change it in its home tab, it updates everywhere else immediately. Nobody should ever need to copy a value between tabs by hand.
B8: Colour legend
B9: Text is plain black everywhere. Row shading instead shows which Stream an item belongs to (applied automatically via conditional formatting, so it updates itself as Stream values change):
B10: US
B11: MyMSC
B12: Rollout / MVP Rollout
B13: Backlog / Growth
B14: Tech Enhancements
B15: PI11, PI12, or any other PI-specific stream
... B22: Tab ownership — who edits what
B23: Tab | C23: Owner | D23: Types here (input) | E23: Shown automatically (pulled)
B24: Backlog | C24: Anyone (entry point) | D24: Requirement Name, Type, Stream, Status, Date Added, Create Jira Ticket?, Jira Key | E24: Jira Link, Priority, Sprint, Release
B25: API Design Planning | C25: API Design Lead | D25: RAML Required, RAML Delivery Date, Assignee, Priority, Design Status, Handover | E25: Requirement Name, Stream, Jira Link, Status, Sprint
B26: RTM | C26: BA | D26: Predecessor, Successor, Dependency Status, Notes | E26: Requirement Name, Stream, Jira Link, Status, Priority, Sprint
B27: Sprint Planning | C27: BA / PO / SM | D27: Sprint, HLE | E27: Requirement Name, Stream, Priority, Status
B28: Roadmap | C28: Nobody — all view | D28: (fully automatic) | E28: Stream x Sprint HLE grid
B29: Release | C29: DM / SM | D29: Release | E29: Requirement Name, Stream, Sprint, Status, Priority, HLE
B31: Status: template only
B32: This workbook is currently a clean, empty structure — no data has been migrated yet. Automations planned for later phases are NOT yet wired up:
B33: 1. Jira (labelled ticket) -> auto-creates a Backlog row with Jira Key/Link filled in.
B34: 2. Any new Backlog row (Jira-sourced or typed straight in with no Jira ticket) -> auto-creates a Trello card.
B35: 3. Sprint changed for an item -> updates the sprint label on its Trello card.
B36: 4. 'Create Jira Ticket?' set to Yes on a manually-added row -> creates the Jira issue and writes the key back into Jira Key/Jira Link, then flips the flag to Created.
B37: 5. Scheduled refresh of the RTM Dependency Status column from the live status of the Predecessor/Successor Jira key.
B39: Until these are wired up, fill in Jira Key, Predecessor/Successor, and Dependency Status manually.
B41: Sprint Planning sort order
B42: Sprint Planning is kept sorted ascending by Sprint (lowest in-scope sprint first, unassigned/'To Plan' last), using a hidden 'Sort Key' column (H) that converts the Sprint text to a number. If you add new rows and want to re-sort, select the table and use Data > Sort by column H — don't unhide/delete that column.
B44: Release tab population
B45: The Release tab lists every item that has a real Sprint assigned in Sprint Planning (not blank/'To Plan') — once an item gets a sprint for the first time, add its Requirement ID to the Release tab so DM/SM can assign it a Release. This mirrors how RTM/Sprint Planning/API Design Planning already work: copy the ID over when the item reaches that stage.
... B50: The Sprint->Quarter mapping only covers 2026 right now (Sprint 1-16, Q1-Q4). It will need updating on the Lists sheet every year, since sprint numbering and quarter week boundaries reset annually and a new set of 4 quarterly tabs will need creating for the new year.

Sheet Backlog
A1: Requirement ID | B1: Requirement Name | C1: Type | D1: Stream | E1: Stream Owner | F1: Status | G1: Priority | H1: Planned Delivery | I1: Sprint | J1: HLE | K1: Release | L1: Date Added | M1: Create Jira Ticket? | N1: Jira Key | O1: Jira Link | P1: ID Number
A2: NEW-0002 | B2: Whatsapp Subscription (Phase 2) | C2: CR | D2: Backlog | E2: MA | F2: ON HOLD | G2: Medium | H2: Q4 2026 | I2: =IF($A2="","",IFERROR(IF(ISBLANK(INDEX(SprintPlanning[Sprint],MATCH($A2,SprintPlanning[Requirement ID],0))),"To Plan",INDEX(SprintPlanning[Sprint],MATCH($A2,SprintPlanning[Requirement ID],0))),"To Plan")) | K2: =IFERROR(IF(ISBLANK(INDEX(Release[Release],MATCH($A2,Release[Requirement ID],0))),"",INDEX(Release[Release],MATCH($A2,Release[Requirement ID],0))),"") | L2: 46226 | O2: =IF($N2="","","https://smartship.atlassian.net/browse/"&$N2) | P2: =IFERROR(VALUE(MID($A2,5,4)),0)
A3: NEW-0005 | B3: Handling multicabin booking | C3: CR | D3: Growth | E3: B2CW | F3: NEW | G3: Medium | H3: Q4 2026 | I3: =IF($A3="","",IFERROR(IF(ISBLANK(INDEX(SprintPlanning[Sprint],MATCH($A3,SprintPlanning[Requirement ID],0))),"To Plan",INDEX(SprintPlanning[Sprint],MATCH($A3,SprintPlanning[Requirement ID],0))),"To Plan")) | J3: 21 | K3: =IFERROR(IF(ISBLANK(INDEX(Release[Release],MATCH($A3,Release[Requirement ID],0))),"",INDEX(Release[Release],MATCH($A3,Release[Requirement ID],0))),"") | L3: 46226 | O3: =IF($N3="","","https://smartship.atlassian.net/browse/"&$N3) | P3: =IFERROR(VALUE(MID($A3,5,4)),0)
A4: NEW-0006 | B4: New UWO Interface (decoupling) | C4: New | D4: Growth | E4: B2CW | F4: NEW | G4: Medium | H4: Q1 2027 | I4: =IF($A4="","",IFERROR(IF(ISBLANK(INDEX(SprintPlanning[Sprint],MATCH($A4,SprintPlanning[Requirement ID],0))),"To Plan",INDEX(SprintPlanning[Sprint],MATCH($A4,SprintPlanning[Requirement ID],0))),"To Plan")) | J4: 3 | K4: =IFERROR(IF(ISBLANK(INDEX(Release[Release],MATCH($A4,Release[Requirement ID],0))),"",INDEX(Release[Release],MATCH($A4,Release[Requirement ID],0))),"") | L4: 46226 | O4: =IF($N4="","","https://smartship.atlassian.net/browse/"&$N4) | P4: =IFERROR(VALUE(MID($A4,5,4)),0)
A5: NEW-0007 | B5: Update Hold option (decoupling) | C5: CR | D5: Growth | E5: B2CW | F5: NEW | G5: Medium | H5: Q1 2027 | I5: =IF($A5="","",IFERROR(IF(ISBLANK(INDEX(SprintPlanning[Sprint],MATCH($A5,SprintPlanning[Requirement ID],0))),"To Plan",INDEX(SprintPlanning[Sprint],MATCH($A5,SprintPlanning[Requirement ID],0))),"To Plan")) | J5: 3 | K5: =IFERROR(IF(ISBLANK(INDEX(Release[Release],MATCH($A5,Release[Requirement ID],0))),"",INDEX(Release[Release],MATCH($A5,Release[Requirement ID],0))),"") | L5: 46226 | O5: =IF($N5="","","https://smartship.atlassian.net/browse/"&$N5) | P5: =IFERROR(VALUE(MID($A5,5,4)),0)
A6: NEW-0011 | B6: INT 101 - Cabin Selections (Booking Group Management) | C6: CR | D6: Growth | E6: S&S | F6: NEW | G6: Medium | H6: Q4 2026 | I6: =IF($A6="","",IFERROR(IF(ISBLANK(INDEX(SprintPlanning[Sprint],MATCH($A6,SprintPlanning[Requirement ID],0))),"To Plan",INDEX(SprintPlanning[Sprint],MATCH($A6,SprintPlanning[Requirement ID],0))),"To Plan")) | J6: 8 | K6: =IFERROR(IF(ISBLANK(INDEX(Release[Release],MATCH($A6,Release[Requirement ID],0))),"",INDEX(Release[Release],MATCH($A6,Release[Requirement ID],0))),"") | L6: 46226 | M6: Created | N6: MDTTPU-8135 | O6: =IF($N6="","","https://smartship.atlassian.net/browse/"&$N6) | P6: =IFERROR(VALUE(MID($A6,5,4)),0)
A7: NEW-0016 | B7: myMSC Add USA Market Configuration - Chain 1/ Chain 2 | C7: Config | D7: US | E7: B2CW | F7: NEW | G7: Medium | H7: Q3 2026 | I7: =IF($A7="","",IFERROR(IF(ISBLANK(INDEX(SprintPlanning[Sprint],MATCH($A7,SprintPlanning[Requirement ID],0))),"To Plan",INDEX(SprintPlanning[Sprint],MATCH($A7,SprintPlanning[Requirement ID],0))),"To Plan")) | J7: 8 | K7: =IFERROR(IF(ISBLANK(INDEX(Release[Release],MATCH($A7,Release[Requirement ID],0))),"",INDEX(Release[Release],MATCH($A7,Release[Requirement ID],0))),"") | L7: 46226 | M7: Created | N7: MDTTPU-13662 | O7: =IF($N7="","","https://smartship.atlassian.net/browse/"&$N7) | P7: =IFERROR(VALUE(MID($A7,5,4)),0)
A8: NEW-0017 | B8: ARG Payment provider Pagtur | C8: New | D8: MVP Rollout | E8: B2CW | F8: NEW | G8: Medium | H8: Q1 2027 | I8: =IF($A8="","",IFERROR(IF(ISBLANK(INDEX(SprintPlanning[Sprint],MATCH($A8,SprintPlanning[Requirement ID],0))),"To Plan",INDEX(SprintPlanning[Sprint],MATCH($A8,SprintPlanning[Requirement ID],0))),"To Plan")) | J8: 40 | K8: =IFERROR(IF(ISBLANK(INDEX(Release[Release],MATCH($A8,Release[Requirement ID],0))),"",INDEX(Release[Release],MATCH($A8,Release[Requirement ID],0))),"") | L8: 46226 | O8: =IF($N8="","","https://smartship.atlassian.net/browse/"&$N8) | P8: =IFERROR(VALUE(MID($A8,5,4)),0)
A9: NEW-0018 | B9: BR Payment providerDireçao | C9: New | D9: MVP Rollout | E9: B2CW | F9: NEW | G9: Medium | H9: Q1 2027 | I9: =IF($A9="","",IFERROR(IF(ISBLANK(INDEX(SprintPlanning[Sprint],MATCH($A9,SprintPlanning[Requirement ID],0))),"To Plan",INDEX(SprintPlanning[Sprint],MATCH($A9,SprintPlanning[Requirement ID],0))),"To Plan")) | J9: 40 | K9: =IFERROR(IF(ISBLANK(INDEX(Release[Release],MATCH($A9,Release[Requirement ID],0))),"",INDEX(Release[Release],MATCH($A9,Release[Requirement ID],0))),"") | L9: 46226 | O9: =IF($N9="","","https://smartship.atlassian.net/browse/"&$N9) | P9: =IFERROR(VALUE(MID($A9,5,4)),0)
A10: NEW-0020 | B10: MyMSC Spa | C10: New | D10: MyMSC | E10: B2CW | F10: NEW | G10: Medium | I10: =IF($A10="","",IFERROR(IF(ISBLANK(INDEX(SprintPlanning[Sprint],MATCH($A10,SprintPlanning[Requirement ID],0))),"To Plan",INDEX(SprintPlanning[Sprint],MATCH($A10,SprintPlanning[Requirement ID],0))),"To Plan")) | J10: 20 | K10: =IFERROR(IF(ISBLANK(INDEX(Release[Release],MATCH($A10,Release[Requirement ID],0))),"",INDEX(Release[Release],MATCH($A10,Release[Requirement ID],0))),"") | L10: 46226 | O10: =IF($N10="","","https://smartship.atlassian.net/browse/"&$N10) | P10: =IFERROR(VALUE(MID($A10,5,4)),0)
A11: NEW-0022 | B11: Super Agency Access | C11: New | D11: MyMSC | E11: B2CW | F11: NEW | G11: Medium | I11: =IF($A11="","",IFERROR(IF(ISBLANK(INDEX(SprintPlanning[Sprint],MATCH($A11,SprintPlanning[Requirement ID],0))),"To Plan",INDEX(SprintPlanning[Sprint],MATCH($A11,SprintPlanning[Requirement ID],0))),"To Plan")) | J11: 8 | K11: =IFERROR(IF(ISBLANK(INDEX(Release[Release],MATCH($A11,Release[Requirement ID],0))),"",INDEX(Release[Release],MATCH($A11,Release[Requirement ID],0))),"") | L11: 46226 | O11: =IF($N11="","","https://smartship.atlassian.net/browse/"&$N11) | P11: =IFERROR(VALUE(MID($A11,5,4)),0)
A12: NEW-0033 | B12: Pending Configurations for DACH, MED, LATAM | C12: Config | D12: MyMSC | E12: B2CW | F12: NEW | G12: Medium | I12: =IF($A12="","",IFERROR(IF(ISBLANK(INDEX(SprintPlanning[Sprint],MATCH($A12,SprintPlanning[Requirement ID],0))),"To Plan",INDEX(SprintPlanning[Sprint],MATCH($A12,SprintPlanning[Requirement ID],0))),"To Plan")) | J12: 3 | K12: =IFERROR(IF(ISBLANK(INDEX(Release[Release],MATCH($A12,Release[Requirement ID],0))),"",INDEX(Release[Release],MATCH($A12,Release[Requirement ID],0))),"") | L12: 46226 | M12: Created | N12: DTTP25-21230 | O12: =IF($N12="","","https://smartship.atlassian.net/browse/"&$N12) | P12: =IFERROR(VALUE(MID($A12,5,4)),0)
A13: NEW-0068 | B13: [EAINT] [CR][INT026][INT133][INT130] Split calls to CMS for excursion/OBS data into chunks | C13: CR | D13: MyMSC | E13: B2CW | F13: NEW | G13: Medium | I13: =IF($A13="","",IFERROR(IF(ISBLANK(INDEX(SprintPlanning[Sprint],MATCH($A13,SprintPlanning[Requirement ID],0))),"To Plan",INDEX(SprintPlanning[Sprint],MATCH($A13,SprintPlanning[Requirement ID],0))),"To Plan")) | J13: 8 | K13: =IFERROR(IF(ISBLANK(INDEX(Release[Release],MATCH($A13,Release[Requirement ID],0))),"",INDEX(Release[Release],MATCH($A13,Release[Requirement ID],0))),"") | L13: 46226 | O13: =IF($N13="","","https://smartship.atlassian.net/browse/"&$N13) | P13: =IFERROR(VALUE(MID($A13,5,4)),0)
A14: NEW-0265 | B14: TLI 99.1 | C14: TBC | D14: US | E14: MA | F14: NA | G14: Medium | I14: =IF($A14="","",IFERROR(IF(ISBLANK(INDEX(SprintPlanning[Sprint],MATCH($A14,SprintPlanning[Requirement ID],0))),"To Plan",INDEX(SprintPlanning[Sprint],MATCH($A14,SprintPlanning[Requirement ID],0))),"To Plan")) | K14: =IFERROR(IF(ISBLANK(INDEX(Release[Release],MATCH($A14,Release[Requirement ID],0))),"",INDEX(Release[Release],MATCH($A14,Release[Requirement ID],0))),"") | L14: 46232 | O14: =IF($N14="","","https://smartship.atlassian.net/browse/"&$N14) | P14: =IFERROR(VALUE(MID($A14,5,4)),0)
A15: NEW-0266 | B15: Campaigns for loyalty program management | C15: TBC | D15: US | E15: MA | F15: NA | G15: Medium | I15: =IF($A15="","",IFERROR(IF(ISBLANK(INDEX(SprintPlanning[Sprint],MATCH($A15,SprintPlanning[Requirement ID],0))),"To Plan",INDEX(SprintPlanning[Sprint],MATCH($A15,SprintPlanning[Requirement ID],0))),"To Plan")) | K15: =IFERROR(IF(ISBLANK(INDEX(Release[Release],MATCH($A15,Release[Requirement ID],0))),"",INDEX(Release[Release],MATCH($A15,Release[Requirement ID],0))),"") | L15: 46232 | O15: =IF($N15="","","https://smartship.atlassian.net/browse/"&$N15) | P15: =IFERROR(VALUE(MID($A15,5,4)),0)
A16: NEW-0270 | B16: Booking Group Management Cabin Selections | C16: CR | D16: US | E16: B2CW | F16: NEW | G16: Medium | I16: =IF($A16="","",IFERROR(IF(ISBLANK(INDEX(SprintPlanning[Sprint],MATCH($A16,SprintPlanning[Requirement ID],0))),"To Plan",INDEX(SprintPlanning[Sprint],MATCH($A16,SprintPlanning[Requirement ID],0))),"To Plan")) | J16: 5 | K16: =IFERROR(IF(ISBLANK(INDEX(Release[Release],MATCH($A16,Release[Requirement ID],0))),"",INDEX(Release[Release],MATCH($A16,Release[Requirement ID],0))),"") | L16: 46232 | O16: =IF($N16="","","https://smartship.atlassian.net/browse/"&$N16) | P16: =IFERROR(VALUE(MID($A16,5,4)),0)
A17: NEW-0274 | B17: INT024.2 - Addition of “Disembarkation Date” and “Pay By” fields | C17: CR | D17: Growth | E17: S&S | F17: NEW | G17: Medium | I17: =IF($A17="","",IFERROR(IF(ISBLANK(INDEX(SprintPlanning[Sprint],MATCH($A17,SprintPlanning[Requirement ID],0))),"To Plan",INDEX(SprintPlanning[Sprint],MATCH($A17,SprintPlanning[Requirement ID],0))),"To Plan")) | J17: 3 | K17: =IFERROR(IF(ISBLANK(INDEX(Release[Release],MATCH($A17,Release[Requirement ID],0))),"",INDEX(Release[Release],MATCH($A17,Release[Requirement ID],0))),"") | L17: 46232 | O17: =IF($N17="","","https://smartship.atlassian.net/browse/"&$N17) | P17: =IFERROR(VALUE(MID($A17,5,4)),0)
A18: NEW-0284 | B18: DACH, MED, LATAM Configurations | C18: CR | D18: MyMSC | E18: B2CW | F18: NEW | G18: Medium | I18: =IF($A18="","",IFERROR(IF(ISBLANK(INDEX(SprintPlanning[Sprint],MATCH($A18,SprintPlanning[Requirement ID],0))),"To Plan",INDEX(SprintPlanning[Sprint],MATCH($A18,SprintPlanning[Requirement ID],0))),"To Plan")) | K18: =IFERROR(IF(ISBLANK(INDEX(Release[Release],MATCH($A18,Release[Requirement ID],0))),"",INDEX(Release[Release],MATCH($A18,Release[Requirement ID],0))),"") | L18: 46232 | O18: =IF($N18="","","https://smartship.atlassian.net/browse/"&$N18) | P18: =IFERROR(VALUE(MID($A18,5,4)),0)
A19: NEW-0288 | B19: Remove of login endpoints from MyMSC EAPI | C19: Tech Task | D19: MyMSC | E19: ALL | F19: NEW | G19: Medium | I19: =IF($A19="","",IFERROR(IF(ISBLANK(INDEX(SprintPlanning[Sprint],MATCH($A19,SprintPlanning[Requirement ID],0))),"To Plan",INDEX(SprintPlanning[Sprint],MATCH($A19,SprintPlanning[Requirement ID],0))),"To Plan")) | J19: 8 | K19: =IFERROR(IF(ISBLANK(INDEX(Release[Release],MATCH($A19,Release[Requirement ID],0))),"",INDEX(Release[Release],MATCH($A19,Release[Requirement ID],0))),"") | L19: 46232 | O19: =IF($N19="","","https://smartship.atlassian.net/browse/"&$N19) | P19: =IFERROR(VALUE(MID($A19,5,4)),0)
A20: NEW-0290 | B20: Bug fix for cabin logic in INT135.1/135.2 | C20: Bug | D20: MyMSC | E20: B2CW | F20: NEW | G20: Medium | I20: =IF($A20="","",IFERROR(IF(ISBLANK(INDEX(SprintPlanning[Sprint],MATCH($A20,SprintPlanning[Requirement ID],0))),"To Plan",INDEX(SprintPlanning[Sprint],MATCH($A20,SprintPlanning[Requirement ID],0))),"To Plan")) | K20: =IFERROR(IF(ISBLANK(INDEX(Release[Release],MATCH($A20,Release[Requirement ID],0))),"",INDEX(Release[Release],MATCH($A20,Release[Requirement ID],0))),"") | L20: 46232 | O20: =IF($N20="","","https://smartship.atlassian.net/browse/"&$N20) | P20: =IFERROR(VALUE(MID($A20,5,4)),0)
A21: NEW-0299 | B21: Spa | C21: CR | D21: MyMSC | E21: B2CW | F21: NEW | G21: Medium | I21: =IF($A21="","",IFERROR(IF(ISBLANK(INDEX(SprintPlanning[Sprint],MATCH($A21,SprintPlanning[Requirement ID],0))),"To Plan",INDEX(SprintPlanning[Sprint],MATCH($A21,SprintPlanning[Requirement ID],0))),"To Plan")) | J21: 33 | K21: =IFERROR(IF(ISBLANK(INDEX(Release[Release],MATCH($A21,Release[Requirement ID],0))),"",INDEX(Release[Release],MATCH($A21,Release[Requirement ID],0))),"") | L21: 46232 | O21: =IF($N21="","","https://smartship.atlassian.net/browse/"&$N21) | P21: =IFERROR(VALUE(MID($A21,5,4)),0)
A22: NEW-0315 | B22: MyMSC CR to handle BKG_001 when booking retrieved | C22: CR | D22: MyMSC | E22: B2CW | F22: NEW | G22: Medium | I22: =IF($A22="","",IFERROR(IF(ISBLANK(INDEX(SprintPlanning[Sprint],MATCH($A22,SprintPlanning[Requirement ID],0))),"To Plan",INDEX(SprintPlanning[Sprint],MATCH($A22,SprintPlanning[Requirement ID],0))),"To Plan")) | J22: 8 | K22: =IFERROR(IF(ISBLANK(INDEX(Release[Release],MATCH($A22,Release[Requirement ID],0))),"",INDEX(Release[Release],MATCH($A22,Release[Requirement ID],0))),"") | L22: 46232 | O22: =IF($N22="","","https://smartship.atlassian.net/browse/"&$N22) | P22: =IFERROR(VALUE(MID($A22,5,4)),0)
A23: NEW-0322 | B23: MyMSC/MA CR for enabling DEM links to light login | C23: CR | D23: MyMSC | E23: B2CW | F23: NEW | G23: Medium | I23: =IF($A23="","",IFERROR(IF(ISBLANK(INDEX(SprintPlanning[Sprint],MATCH($A23,SprintPlanning[Requirement ID],0))),"To Plan",INDEX(SprintPlanning[Sprint],MATCH($A23,SprintPlanning[Requirement ID],0))),"To Plan")) | J23: 13 | K23: =IFERROR(IF(ISBLANK(INDEX(Release[Release],MATCH($A23,Release[Requirement ID],0))),"",INDEX(Release[Release],MATCH($A23,Release[Requirement ID],0))),"") | L23: 46232 | O23: =IF($N23="","","https://smartship.atlassian.net/browse/"&$N23) | P23: =IFERROR(VALUE(MID($A23,5,4)),0)
A24: NEW-0324 | B24: MSC- MyMSC PRE_CRM_002 error scenario change CR to additem | C24: CR | D24: MyMSC | E24: B2CW | F24: NEW | G24: Medium | I24: =IF($A24="","",IFERROR(IF(ISBLANK(INDEX(SprintPlanning[Sprint],MATCH($A24,SprintPlanning[Requirement ID],0))),"To Plan",INDEX(SprintPlanning[Sprint],MATCH($A24,SprintPlanning[Requirement ID],0))),"To Plan")) | K24: =IFERROR(IF(ISBLANK(INDEX(Release[Release],MATCH($A24,Release[Requirement ID],0))),"",INDEX(Release[Release],MATCH($A24,Release[Requirement ID],0))),"") | L24: 46232 | O24: =IF($N24="","","https://smartship.atlassian.net/browse/"&$N24) | P24: =IFERROR(VALUE(MID($A24,5,4)),0)
A25: NEW-0343 | B25: CDP / DTS Post Booking - CR - Passenger name filter | C25: CR | D25: Backlog | E25: MA | F25: ON HOLD | G25: Medium | I25: =IF($A25="","",IFERROR(IF(ISBLANK(INDEX(SprintPlanning[Sprint],MATCH($A25,SprintPlanning[Requirement ID],0))),"To Plan",INDEX(SprintPlanning[Sprint],MATCH($A25,SprintPlanning[Requirement ID],0))),"To Plan")) | K25: =IFERROR(IF(ISBLANK(INDEX(Release[Release],MATCH($A25,Release[Requirement ID],0))),"",INDEX(Release[Release],MATCH($A25,Release[Requirement ID],0))),"") | L25: 46232 | O25: =IF($N25="","","https://smartship.atlassian.net/browse/"&$N25) | P25: =IFERROR(VALUE(MID($A25,5,4)),0)
A26: NEW-0344 | B26: CDP / DTS Post Booking - CR - INT024.1 Improve data quality handling and optimise customer search | C26: CR | D26: Backlog | E26: MA | F26: NEW | G26: Medium | I26: =IF($A26="","",IFERROR(IF(ISBLANK(INDEX(SprintPlanning[Sprint],MATCH($A26,SprintPlanning[Requirement ID],0))),"To Plan",INDEX(SprintPlanning[Sprint],MATCH($A26,SprintPlanning[Requirement ID],0))),"To Plan")) | K26: =IFERROR(IF(ISBLANK(INDEX(Release[Release],MATCH($A26,Release[Requirement ID],0))),"",INDEX(Release[Release],MATCH($A26,Release[Requirement ID],0))),"") | L26: 46232 | O26: =IF($N26="","","https://smartship.atlassian.net/browse/"&$N26) | P26: =IFERROR(VALUE(MID($A26,5,4)),0)
A27: NEW-0345 | B27: CDP / DTS Post Booking - CR - INT024.1 Long term Improved data quality handling | C27: CR | D27: Backlog | E27: MA | F27: NEW | G27: Medium | I27: =IF($A27="","",IFERROR(IF(ISBLANK(INDEX(SprintPlanning[Sprint],MATCH($A27,SprintPlanning[Requirement ID],0))),"To Plan",INDEX(SprintPlanning[Sprint],MATCH($A27,SprintPlanning[Requirement ID],0))),"To Plan")) | K27: =IFERROR(IF(ISBLANK(INDEX(Release[Release],MATCH($A27,Release[Requirement ID],0))),"",INDEX(Release[Release],MATCH($A27,Release[Requirement ID],0))),"") | L27: 46232 | O27: =IF($N27="","","https://smartship.atlassian.net/browse/"&$N27) | P27: =IFERROR(VALUE(MID($A27,5,4)),0)
A28: NEW-0346 | B28: CR - Improved data quality handling optimise customer search page size across other integrations | C28: CR | D28: Backlog | E28: MA | F28: NEW | G28: Medium | I28: =IF($A28="","",IFERROR(IF(ISBLANK(INDEX(SprintPlanning[Sprint],MATCH($A28,SprintPlanning[Requirement ID],0))),"To Plan",INDEX(SprintPlanning[Sprint],MATCH($A28,SprintPlanning[Requirement ID],0))),"To Plan")) | K28: =IFERROR(IF(ISBLANK(INDEX(Release[Release],MATCH($A28,Release[Requirement ID],0))),"",INDEX(Release[Release],MATCH($A28,Release[Requirement ID],0))),"") | L28: 46232 | O28: =IF($N28="","","https://smartship.atlassian.net/browse/"&$N28) | P28: =IFERROR(VALUE(MID($A28,5,4)),0)
A29: NEW-0356 | B29: MED Insurance - Do not sell any insurance if CoR differ across pax | C29: CR | D29: Growth | E29: B2CW | F29: ON HOLD | G29: Medium | I29: =IF($A29="","",IFERROR(IF(ISBLANK(INDEX(SprintPlanning[Sprint],MATCH($A29,SprintPlanning[Requirement ID],0))),"To Plan",INDEX(SprintPlanning[Sprint],MATCH($A29,SprintPlanning[Requirement ID],0))),"To Plan")) | J29: 8 | K29: =IFERROR(IF(ISBLANK(INDEX(Release[Release],MATCH($A29,Release[Requirement ID],0))),"",INDEX(Release[Release],MATCH($A29,Release[Requirement ID],0))),"") | L29: 46232 | O29: =IF($N29="","","https://smartship.atlassian.net/browse/"&$N29) | P29: =IFERROR(VALUE(MID($A29,5,4)),0)
A30: NEW-0358 | B30: CMS Configuration for Airports in B2CW Booking Funnel | C30: CR | D30: Growth | E30: B2CW | F30: ON HOLD | G30: Medium | I30: =IF($A30="","",IFERROR(IF(ISBLANK(INDEX(SprintPlanning[Sprint],MATCH($A30,SprintPlanning[Requirement ID],0))),"To Plan",INDEX(SprintPlanning[Sprint],MATCH($A30,SprintPlanning[Requirement ID],0))),"To Plan")) | K30: =IFERROR(IF(ISBLANK(INDEX(Release[Release],MATCH($A30,Release[Requirement ID],0))),"",INDEX(Release[Release],MATCH($A30,Release[Requirement ID],0))),"") | L30: 46232 | O30: =IF($N30="","","https://smartship.atlassian.net/browse/"&$N30) | P30: =IFERROR(VALUE(MID($A30,5,4)),0)
A31: NEW-0360 | B31: Paypal Reconciliation for prepaid | C31: CR | D31: Growth | E31: B2CW | F31: NEW | G31: Medium | H31: Q4 2026 | I31: =IF($A31="","",IFERROR(IF(ISBLANK(INDEX(SprintPlanning[Sprint],MATCH($A31,SprintPlanning[Requirement ID],0))),"To Plan",INDEX(SprintPlanning[Sprint],MATCH($A31,SprintPlanning[Requirement ID],0))),"To Plan")) | J31: 5 | K31: =IFERROR(IF(ISBLANK(INDEX(Release[Release],MATCH($A31,Release[Requirement ID],0))),"",INDEX(Release[Release],MATCH($A31,Release[Requirement ID],0))),"") | L31: 46232 | O31: =IF($N31="","","https://smartship.atlassian.net/browse/"&$N31) | P31: =IFERROR(VALUE(MID($A31,5,4)),0)
A32: NEW-0361 | B32: US - adding of fields to Hold option orchestration in call to AJO -cabincode, embarkation date, cruise area | C32: CR | D32: Growth | E32: MA | F32: NEW | G32: Medium | H32: Q4 2026 | I32: =IF($A32="","",IFERROR(IF(ISBLANK(INDEX(SprintPlanning[Sprint],MATCH($A32,SprintPlanning[Requirement ID],0))),"To Plan",INDEX(SprintPlanning[Sprint],MATCH($A32,SprintPlanning[Requirement ID],0))),"To Plan")) | K32: =IFERROR(IF(ISBLANK(INDEX(Release[Release],MATCH($A32,Release[Requirement ID],0))),"",INDEX(Release[Release],MATCH($A32,Release[Requirement ID],0))),"") | L32: 46232 | O32: =IF($N32="","","https://smartship.atlassian.net/browse/"&$N32) | P32: =IFERROR(VALUE(MID($A32,5,4)),0)
A33: NEW-0362 | B33: US - Known and Unknown management analysis for US (CDP/AJO) | C33: CR | D33: Growth | E33: MA | F33: NEW | G33: Medium | H33: Q4 2026 | I33: =IF($A33="","",IFERROR(IF(ISBLANK(INDEX(SprintPlanning[Sprint],MATCH($A33,SprintPlanning[Requirement ID],0))),"To Plan",INDEX(SprintPlanning[Sprint],MATCH($A33,SprintPlanning[Requirement ID],0))),"To Plan")) | K33: =IFERROR(IF(ISBLANK(INDEX(Release[Release],MATCH($A33,Release[Requirement ID],0))),"",INDEX(Release[Release],MATCH($A33,Release[Requirement ID],0))),"") | L33: 46232 | O33: =IF($N33="","","https://smartship.atlassian.net/browse/"&$N33) | P33: =IFERROR(VALUE(MID($A33,5,4)),0)
A34: NEW-0363 | B34: US - Outbound Leads - Light Login for Leads Moving Option Expiring | C34: CR | D34: Growth | E34: B2CW | F34: NEW | G34: Medium | H34: Q4 2026 | I34: =IF($A34="","",IFERROR(IF(ISBLANK(INDEX(SprintPlanning[Sprint],MATCH($A34,SprintPlanning[Requirement ID],0))),"To Plan",INDEX(SprintPlanning[Sprint],MATCH($A34,SprintPlanning[Requirement ID],0))),"To Plan")) | K34: =IFERROR(IF(ISBLANK(INDEX(Release[Release],MATCH($A34,Release[Requirement ID],0))),"",INDEX(Release[Release],MATCH($A34,Release[Requirement ID],0))),"") | L34: 46232 | O34: =IF($N34="","","https://smartship.atlassian.net/browse/"&$N34) | P34: =IFERROR(VALUE(MID($A34,5,4)),0)
A35: NEW-0364 | B35: B2CW Booking Funnel - TRF and Pricing Structure Assessment – ESP Market | C35: CR | D35: Growth | E35: B2CW | F35: NEW | G35: Medium | H35: Q4 2026 | I35: =IF($A35="","",IFERROR(IF(ISBLANK(INDEX(SprintPlanning[Sprint],MATCH($A35,SprintPlanning[Requirement ID],0))),"To Plan",INDEX(SprintPlanning[Sprint],MATCH($A35,SprintPlanning[Requirement ID],0))),"To Plan")) | K35: =IFERROR(IF(ISBLANK(INDEX(Release[Release],MATCH($A35,Release[Requirement ID],0))),"",INDEX(Release[Release],MATCH($A35,Release[Requirement ID],0))),"") | L35: 46232 | O35: =IF($N35="","","https://smartship.atlassian.net/browse/"&$N35) | P35: =IFERROR(VALUE(MID($A35,5,4)),0)
A36: NEW-0366 | B36: B2CW Accessibility & Medical Webform Business Rules for booking | C36: CR | D36: Growth | E36: B2CW | F36: NEW | G36: Medium | H36: Q4 2026 | I36: =IF($A36="","",IFERROR(IF(ISBLANK(INDEX(SprintPlanning[Sprint],MATCH($A36,SprintPlanning[Requirement ID],0))),"To Plan",INDEX(SprintPlanning[Sprint],MATCH($A36,SprintPlanning[Requirement ID],0))),"To Plan")) | K36: =IFERROR(IF(ISBLANK(INDEX(Release[Release],MATCH($A36,Release[Requirement ID],0))),"",INDEX(Release[Release],MATCH($A36,Release[Requirement ID],0))),"") | L36: 46232 | O36: =IF($N36="","","https://smartship.atlassian.net/browse/"&$N36) | P36: =IFERROR(VALUE(MID($A36,5,4)),0)
A37: NEW-0367 | B37: MyMSC US | Extend JWT expiry | C37: CR | D37: Growth | E37: B2CW | F37: NEW | G37: Medium | H37: Q4 2026 | I37: =IF($A37="","",IFERROR(IF(ISBLANK(INDEX(SprintPlanning[Sprint],MATCH($A37,SprintPlanning[Requirement ID],0))),"To Plan",INDEX(SprintPlanning[Sprint],MATCH($A37,SprintPlanning[Requirement ID],0))),"To Plan")) | J37: 5 | K37: =IFERROR(IF(ISBLANK(INDEX(Release[Release],MATCH($A37,Release[Requirement ID],0))),"",INDEX(Release[Release],MATCH($A37,Release[Requirement ID],0))),"") | L37: 46232 | O37: =IF($N37="","","https://smartship.atlassian.net/browse/"&$N37) | P37: =IFERROR(VALUE(MID($A37,5,4)),0)
A38: NEW-0370 | B38: Handling DSC_076 scenario in booking funnel | C38: CR | D38: Growth | E38: B2CW | G38: Medium | I38: =IF($A38="","",IFERROR(IF(ISBLANK(INDEX(SprintPlanning[Sprint],MATCH($A38,SprintPlanning[Requirement ID],0))),"To Plan",INDEX(SprintPlanning[Sprint],MATCH($A38,SprintPlanning[Requirement ID],0))),"To Plan")) | K38: =IFERROR(IF(ISBLANK(INDEX(Release[Release],MATCH($A38,Release[Requirement ID],0))),"",INDEX(Release[Release],MATCH($A38,Release[Requirement ID],0))),"") | L38: 46232 | O38: =IF($N38="","","https://smartship.atlassian.net/browse/"&$N38) | P38: =IFERROR(VALUE(MID($A38,5,4)),0)
A39: NEW-0371 | B39: B2CW Prospect Onsite Quotation | C39: TBC | D39: Growth | E39: B2CW | F39: NEW | G39: Medium | I39: =IF($A39="","",IFERROR(IF(ISBLANK(INDEX(SprintPlanning[Sprint],MATCH($A39,SprintPlanning[Requirement ID],0))),"To Plan",INDEX(SprintPlanning[Sprint],MATCH($A39,SprintPlanning[Requirement ID],0))),"To Plan")) | J39: 5 | K39: =IFERROR(IF(ISBLANK(INDEX(Release[Release],MATCH($A39,Release[Requirement ID],0))),"",INDEX(Release[Release],MATCH($A39,Release[Requirement ID],0))),"") | L39: 46232 | O39: =IF($N39="","","https://smartship.atlassian.net/browse/"&$N39) | P39: =IFERROR(VALUE(MID($A39,5,4)),0)
A40: NEW-0373 | B40: Booking Funnel - AI Optimisation | C40: Tech Task | D40: Backlog / Tech Enh | E40: ALL | F40: NEW | G40: Medium | I40: =IF($A40="","",IFERROR(IF(ISBLANK(INDEX(SprintPlanning[Sprint],MATCH($A40,SprintPlanning[Requirement ID],0))),"To Plan",INDEX(SprintPlanning[Sprint],MATCH($A40,SprintPlanning[Requirement ID],0))),"To Plan")) | K40: =IFERROR(IF(ISBLANK(INDEX(Release[Release],MATCH($A40,Release[Requirement ID],0))),"",INDEX(Release[Release],MATCH($A40,Release[Requirement ID],0))),"") | L40: 46232 | O40: =IF($N40="","","https://smartship.atlassian.net/browse/"&$N40) | P40: =IFERROR(VALUE(MID($A40,5,4)),0)
...

Sheet API Design Planning
A1: Requirement ID | B1: Requirement Name | C1: Stream | D1: Jira Link | E1: Status | F1: Sprint | G1: RAML Required | H1: RAML Delivery Date | I1: Assignee | J1: Priority | K1: Design Status | L1: Handover
A2: NEW-0001 | B2: =IFERROR(IF(ISBLANK(INDEX(Backlog[Requirement Name],MATCH($A2,Backlog[Requirement ID],0))),"",INDEX(Backlog[Requirement Name],MATCH($A2,Backlog[Requirement ID],0))),"") | C2: =IFERROR(IF(ISBLANK(INDEX(Backlog[Stream],MATCH($A2,Backlog[Requirement ID],0))),"",INDEX(Backlog[Stream],MATCH($A2,Backlog[Requirement ID],0))),"") | D2: =IFERROR(IF(ISBLANK(INDEX(Backlog[Jira Link],MATCH($A2,Backlog[Requirement ID],0))),"",INDEX(Backlog[Jira Link],MATCH($A2,Backlog[Requirement ID],0))),"") | E2: =IFERROR(IF(ISBLANK(INDEX(Backlog[Status],MATCH($A2,Backlog[Requirement ID],0))),"",INDEX(Backlog[Status],MATCH($A2,Backlog[Requirement ID],0))),"") | F2: =IFERROR(IF(ISBLANK(INDEX(SprintPlanning[Sprint],MATCH($A2,SprintPlanning[Requirement ID],0))),"",INDEX(SprintPlanning[Sprint],MATCH($A2,SprintPlanning[Requirement ID],0))),"") | J2: =IFERROR(IF(ISBLANK(INDEX(Backlog[Priority],MATCH($A2,Backlog[Requirement ID],0))),"",INDEX(Backlog[Priority],MATCH($A2,Backlog[Requirement ID],0))),"")
A3: NEW-0002 | B3: =IFERROR(IF(ISBLANK(INDEX(Backlog[Requirement Name],MATCH($A3,Backlog[Requirement ID],0))),"",INDEX(Backlog[Requirement Name],MATCH($A3,Backlog[Requirement ID],0))),"") | C3: =IFERROR(IF(ISBLANK(INDEX(Backlog[Stream],MATCH($A3,Backlog[Requirement ID],0))),"",INDEX(Backlog[Stream],MATCH($A3,Backlog[Requirement ID],0))),"") | D3: =IFERROR(IF(ISBLANK(INDEX(Backlog[Jira Link],MATCH($A3,Backlog[Requirement ID],0))),"",INDEX(Backlog[Jira Link],MATCH($A3,Backlog[Requirement ID],0))),"") | E3: =IFERROR(IF(ISBLANK(INDEX(Backlog[Status],MATCH($A3,Backlog[Requirement ID],0))),"",INDEX(Backlog[Status],MATCH($A3,Backlog[Requirement ID],0))),"") | F3: =IFERROR(IF(ISBLANK(INDEX(SprintPlanning[Sprint],MATCH($A3,SprintPlanning[Requirement ID],0))),"",INDEX(SprintPlanning[Sprint],MATCH($A3,SprintPlanning[Requirement ID],0))),"") | J3: =IFERROR(IF(ISBLANK(INDEX(Backlog[Priority],MATCH($A3,Backlog[Requirement ID],0))),"",INDEX(Backlog[Priority],MATCH($A3,Backlog[Requirement ID],0))),"")
A4: NEW-0003 | B4: =IFERROR(IF(ISBLANK(INDEX(Backlog[Requirement Name],MATCH($A4,Backlog[Requirement ID],0))),"",INDEX(Backlog[Requirement Name],MATCH($A4,Backlog[Requirement ID],0))),"") | C4: =IFERROR(IF(ISBLANK(INDEX(Backlog[Stream],MATCH($A4,Backlog[Requirement ID],0))),"",INDEX(Backlog[Stream],MATCH($A4,Backlog[Requirement ID],0))),"") | D4: =IFERROR(IF(ISBLANK(INDEX(Backlog[Jira Link],MATCH($A4,Backlog[Requirement ID],0))),"",INDEX(Backlog[Jira Link],MATCH($A4,Backlog[Requirement ID],0))),"") | E4: =IFERROR(IF(ISBLANK(INDEX(Backlog[Status],MATCH($A4,Backlog[Requirement ID],0))),"",INDEX(Backlog[Status],MATCH($A4,Backlog[Requirement ID],0))),"") | F4: =IFERROR(IF(ISBLANK(INDEX(SprintPlanning[Sprint],MATCH($A4,SprintPlanning[Requirement ID],0))),"",INDEX(SprintPlanning[Sprint],MATCH($A4,SprintPlanning[Requirement ID],0))),"") | J4: =IFERROR(IF(ISBLANK(INDEX(Backlog[Priority],MATCH($A4,Backlog[Requirement ID],0))),"",INDEX(Backlog[Priority],MATCH($A4,Backlog[Requirement ID],0))),"")
A5: NEW-0005 | B5: =IFERROR(IF(ISBLANK(INDEX(Backlog[Requirement Name],MATCH($A5,Backlog[Requirement ID],0))),"",INDEX(Backlog[Requirement Name],MATCH($A5,Backlog[Requirement ID],0))),"") | C5: =IFERROR(IF(ISBLANK(INDEX(Backlog[Stream],MATCH($A5,Backlog[Requirement ID],0))),"",INDEX(Backlog[Stream],MATCH($A5,Backlog[Requirement ID],0))),"") | D5: =IFERROR(IF(ISBLANK(INDEX(Backlog[Jira Link],MATCH($A5,Backlog[Requirement ID],0))),"",INDEX(Backlog[Jira Link],MATCH($A5,Backlog[Requirement ID],0))),"") | E5: =IFERROR(IF(ISBLANK(INDEX(Backlog[Status],MATCH($A5,Backlog[Requirement ID],0))),"",INDEX(Backlog[Status],MATCH($A5,Backlog[Requirement ID],0))),"") | F5: =IFERROR(IF(ISBLANK(INDEX(SprintPlanning[Sprint],MATCH($A5,SprintPlanning[Requirement ID],0))),"",INDEX(SprintPlanning[Sprint],MATCH($A5,SprintPlanning[Requirement ID],0))),"") | J5: =IFERROR(IF(ISBLANK(INDEX(Backlog[Priority],MATCH($A5,Backlog[Requirement ID],0))),"",INDEX(Backlog[Priority],MATCH($A5,Backlog[Requirement ID],0))),"")
A6: NEW-0006 | B6: =IFERROR(IF(ISBLANK(INDEX(Backlog[Requirement Name],MATCH($A6,Backlog[Requirement ID],0))),"",INDEX(Backlog[Requirement Name],MATCH($A6,Backlog[Requirement ID],0))),"") | C6: =IFERROR(IF(ISBLANK(INDEX(Backlog[Stream],MATCH($A6,Backlog[Requirement ID],0))),"",INDEX(Backlog[Stream],MATCH($A6,Backlog[Requirement ID],0))),"") | D6: =IFERROR(IF(ISBLANK(INDEX(Backlog[Jira Link],MATCH($A6,Backlog[Requirement ID],0))),"",INDEX(Backlog[Jira Link],MATCH($A6,Backlog[Requirement ID],0))),"") | E6: =IFERROR(IF(ISBLANK(INDEX(Backlog[Status],MATCH($A6,Backlog[Requirement ID],0))),"",INDEX(Backlog[Status],MATCH($A6,Backlog[Requirement ID],0))),"") | F6: =IFERROR(IF(ISBLANK(INDEX(SprintPlanning[Sprint],MATCH($A6,SprintPlanning[Requirement ID],0))),"",INDEX(SprintPlanning[Sprint],MATCH($A6,SprintPlanning[Requirement ID],0))),"") | J6: =IFERROR(IF(ISBLANK(INDEX(Backlog[Priority],MATCH($A6,Backlog[Requirement ID],0))),"",INDEX(Backlog[Priority],MATCH($A6,Backlog[Requirement ID],0))),"")
A7: NEW-0007 | B7: =IFERROR(IF(ISBLANK(INDEX(Backlog[Requirement Name],MATCH($A7,Backlog[Requirement ID],0))),"",INDEX(Backlog[Requirement Name],MATCH($A7,Backlog[Requirement ID],0))),"") | C7: =IFERROR(IF(ISBLANK(INDEX(Backlog[Stream],MATCH($A7,Backlog[Requirement ID],0))),"",INDEX(Backlog[Stream],MATCH($A7,Backlog[Requirement ID],0))),"") | D7: =IFERROR(IF(ISBLANK(INDEX(Backlog[Jira Link],MATCH($A7,Backlog[Requirement ID],0))),"",INDEX(Backlog[Jira Link],MATCH($A7,Backlog[Requirement ID],0))),"") | E7: =IFERROR(IF(ISBLANK(INDEX(Backlog[Status],MATCH($A7,Backlog[Requirement ID],0))),"",INDEX(Backlog[Status],MATCH($A7,Backlog[Requirement ID],0))),"") | F7: =IFERROR(IF(ISBLANK(INDEX(SprintPlanning[Sprint],MATCH($A7,SprintPlanning[Requirement ID],0))),"",INDEX(SprintPlanning[Sprint],MATCH($A7,SprintPlanning[Requirement ID],0))),"") | J7: =IFERROR(IF(ISBLANK(INDEX(Backlog[Priority],MATCH($A7,Backlog[Requirement ID],0))),"",INDEX(Backlog[Priority],MATCH($A7,Backlog[Requirement ID],0))),"")
A8: NEW-0011 | B8: =IFERROR(IF(ISBLANK(INDEX(Backlog[Requirement Name],MATCH($A8,Backlog[Requirement ID],0))),"",INDEX(Backlog[Requirement Name],MATCH($A8,Backlog[Requirement ID],0))),"") | C8: =IFERROR(IF(ISBLANK(INDEX(Backlog[Stream],MATCH($A8,Backlog[Requirement ID],0))),"",INDEX(Backlog[Stream],MATCH($A8,Backlog[Requirement ID],0))),"") | D8: =IFERROR(IF(ISBLANK(INDEX(Backlog[Jira Link],MATCH($A8,Backlog[Requirement ID],0))),"",INDEX(Backlog[Jira Link],MATCH($A8,Backlog[Requirement ID],0))),"") | E8: =IFERROR(IF(ISBLANK(INDEX(Backlog[Status],MATCH($A8,Backlog[Requirement ID],0))),"",INDEX(Backlog[Status],MATCH($A8,Backlog[Requirement ID],0))),"") | F8: =IFERROR(IF(ISBLANK(INDEX(SprintPlanning[Sprint],MATCH($A8,SprintPlanning[Requirement ID],0))),"",INDEX(SprintPlanning[Sprint],MATCH($A8,SprintPlanning[Requirement ID],0))),"") | J8: =IFERROR(IF(ISBLANK(INDEX(Backlog[Priority],MATCH($A8,Backlog[Requirement ID],0))),"",INDEX(Backlog[Priority],MATCH($A8,Backlog[Requirement ID],0))),"")
A9: NEW-0012 | B9: =IFERROR(IF(ISBLANK(INDEX(Backlog[Requirement Name],MATCH($A9,Backlog[Requirement ID],0))),"",INDEX(Backlog[Requirement Name],MATCH($A9,Backlog[Requirement ID],0))),"") | C9: =IFERROR(IF(ISBLANK(INDEX(Backlog[Stream],MATCH($A9,Backlog[Requirement ID],0))),"",INDEX(Backlog[Stream],MATCH($A9,Backlog[Requirement ID],0))),"") | D9: =IFERROR(IF(ISBLANK(INDEX(Backlog[Jira Link],MATCH($A9,Backlog[Requirement ID],0))),"",INDEX(Backlog[Jira Link],MATCH($A9,Backlog[Requirement ID],0))),"") | E9: =IFERROR(IF(ISBLANK(INDEX(Backlog[Status],MATCH($A9,Backlog[Requirement ID],0))),"",INDEX(Backlog[Status],MATCH($A9,Backlog[Requirement ID],0))),"") | F9: =IFERROR(IF(ISBLANK(INDEX(SprintPlanning[Sprint],MATCH($A9,SprintPlanning[Requirement ID],0))),"",INDEX(SprintPlanning[Sprint],MATCH($A9,SprintPlanning[Requirement ID],0))),"") | J9: =IFERROR(IF(ISBLANK(INDEX(Backlog[Priority],MATCH($A9,Backlog[Requirement ID],0))),"",INDEX(Backlog[Priority],MATCH($A9,Backlog[Requirement ID],0))),"")
A10: NEW-0015 | B10: =IFERROR(IF(ISBLANK(INDEX(Backlog[Requirement Name],MATCH($A10,Backlog[Requirement ID],0))),"",INDEX(Backlog[Requirement Name],MATCH($A10,Backlog[Requirement ID],0))),"") | C10: =IFERROR(IF(ISBLANK(INDEX(Backlog[Stream],MATCH($A10,Backlog[Requirement ID],0))),"",INDEX(Backlog[Stream],MATCH($A10,Backlog[Requirement ID],0))),"") | D10: =IFERROR(IF(ISBLANK(INDEX(Backlog[Jira Link],MATCH($A10,Backlog[Requirement ID],0))),"",INDEX(Backlog[Jira Link],MATCH($A10,Backlog[Requirement ID],0))),"") | E10: =IFERROR(IF(ISBLANK(INDEX(Backlog[Status],MATCH($A10,Backlog[Requirement ID],0))),"",INDEX(Backlog[Status],MATCH($A10,Backlog[Requirement ID],0))),"") | F10: =IFERROR(IF(ISBLANK(INDEX(SprintPlanning[Sprint],MATCH($A10,SprintPlanning[Requirement ID],0))),"",INDEX(SprintPlanning[Sprint],MATCH($A10,SprintPlanning[Requirement ID],0))),"") | J10: =IFERROR(IF(ISBLANK(INDEX(Backlog[Priority],MATCH($A10,Backlog[Requirement ID],0))),"",INDEX(Backlog[Priority],MATCH($A10,Backlog[Requirement ID],0))),"")
A11: NEW-0016 | B11: =IFERROR(IF(ISBLANK(INDEX(Backlog[Requirement Name],MATCH($A11,Backlog[Requirement ID],0))),"",INDEX(Backlog[Requirement Name],MATCH($A11,Backlog[Requirement ID],0))),"") | C11: =IFERROR(IF(ISBLANK(INDEX(Backlog[Stream],MATCH($A11,Backlog[Requirement ID],0))),"",INDEX(Backlog[Stream],MATCH($A11,Backlog[Requirement ID],0))),"") | D11: =IFERROR(IF(ISBLANK(INDEX(Backlog[Jira Link],MATCH($A11,Backlog[Requirement ID],0))),"",INDEX(Backlog[Jira Link],MATCH($A11,Backlog[Requirement ID],0))),"") | E11: =IFERROR(IF(ISBLANK(INDEX(Backlog[Status],MATCH($A11,Backlog[Requirement ID],0))),"",INDEX(Backlog[Status],MATCH($A11,Backlog[Requirement ID],0))),"") | F11: =IFERROR(IF(ISBLANK(INDEX(SprintPlanning[Sprint],MATCH($A11,SprintPlanning[Requirement ID],0))),"",INDEX(SprintPlanning[Sprint],MATCH($A11,SprintPlanning[Requirement ID],0))),"") | J11: =IFERROR(IF(ISBLANK(INDEX(Backlog[Priority],MATCH($A11,Backlog[Requirement ID],0))),"",INDEX(Backlog[Priority],MATCH($A11,Backlog[Requirement ID],0))),"")
A12: NEW-0017 | B12: =IFERROR(IF(ISBLANK(INDEX(Backlog[Requirement Name],MATCH($A12,Backlog[Requirement ID],0))),"",INDEX(Backlog[Requirement Name],MATCH($A12,Backlog[Requirement ID],0))),"") | C12: =IFERROR(IF(ISBLANK(INDEX(Backlog[Stream],MATCH($A12,Backlog[Requirement ID],0))),"",INDEX(Backlog[Stream],MATCH($A12,Backlog[Requirement ID],0))),"") | D12: =IFERROR(IF(ISBLANK(INDEX(Backlog[Jira Link],MATCH($A12,Backlog[Requirement ID],0))),"",INDEX(Backlog[Jira Link],MATCH($A12,Backlog[Requirement ID],0))),"") | E12: =IFERROR(IF(ISBLANK(INDEX(Backlog[Status],MATCH($A12,Backlog[Requirement ID],0))),"",INDEX(Backlog[Status],MATCH($A12,Backlog[Requirement ID],0))),"") | F12: =IFERROR(IF(ISBLANK(INDEX(SprintPlanning[Sprint],MATCH($A12,SprintPlanning[Requirement ID],0))),"",INDEX(SprintPlanning[Sprint],MATCH($A12,SprintPlanning[Requirement ID],0))),"") | J12: =IFERROR(IF(ISBLANK(INDEX(Backlog[Priority],MATCH($A12,Backlog[Requirement ID],0))),"",INDEX(Backlog[Priority],MATCH($A12,Backlog[Requirement ID],0))),"")
A13: NEW-0018 | B13: =IFERROR(IF(ISBLANK(INDEX(Backlog[Requirement Name],MATCH($A13,Backlog[Requirement ID],0))),"",INDEX(Backlog[Requirement Name],MATCH($A13,Backlog[Requirement ID],0))),"") | C13: =IFERROR(IF(ISBLANK(INDEX(Backlog[Stream],MATCH($A13,Backlog[Requirement ID],0))),"",INDEX(Backlog[Stream],MATCH($A13,Backlog[Requirement ID],0))),"") | D13: =IFERROR(IF(ISBLANK(INDEX(Backlog[Jira Link],MATCH($A13,Backlog[Requirement ID],0))),"",INDEX(Backlog[Jira Link],MATCH($A13,Backlog[Requirement ID],0))),"") | E13: =IFERROR(IF(ISBLANK(INDEX(Backlog[Status],MATCH($A13,Backlog[Requirement ID],0))),"",INDEX(Backlog[Status],MATCH($A13,Backlog[Requirement ID],0))),"") | F13: =IFERROR(IF(ISBLANK(INDEX(SprintPlanning[Sprint],MATCH($A13,SprintPlanning[Requirement ID],0))),"",INDEX(SprintPlanning[Sprint],MATCH($A13,SprintPlanning[Requirement ID],0))),"") | J13: =IFERROR(IF(ISBLANK(INDEX(Backlog[Priority],MATCH($A13,Backlog[Requirement ID],0))),"",INDEX(Backlog[Priority],MATCH($A13,Backlog[Requirement ID],0))),"")
... A55: NEW-0099 | B55: =IFERROR(IF(ISBLANK(INDEX(Backlog[Requirement Name],MATCH($A55,Backlog[Requirement ID],0))),"",INDEX(Backlog[Requirement Name],MATCH($A55,Backlog[Requirement ID],0))),"") | C55: =IFERROR(IF(ISBLANK(INDEX(Backlog[Stream],MATCH($A55,Backlog[Requirement ID],0))),"",INDEX(Backlog[Stream],MATCH($A55,Backlog[Requirement ID],0))),"") | D55: =IFERROR(IF(ISBLANK(INDEX(Backlog[Jira Link],MATCH($A55,Backlog[Requirement ID],0))),"",INDEX(Backlog[Jira Link],MATCH($A55,Backlog[Requirement ID],0))),"") | E55: =IFERROR(IF(ISBLANK(INDEX(Backlog[Status],MATCH($A55,Backlog[Requirement ID],0))),"",INDEX(Backlog[Status],MATCH($A55,Backlog[Requirement ID],0))),"") | F55: =IFERROR(IF(ISBLANK(INDEX(SprintPlanning[Sprint],MATCH($A55,SprintPlanning[Requirement ID],0))),"",INDEX(SprintPlanning[Sprint],MATCH($A55,SprintPlanning[Requirement ID],0))),"") | J55: =IFERROR(IF(ISBLANK(INDEX(Backlog[Priority],MATCH($A55,Backlog[Requirement ID],0))),"",INDEX(Backlog[Priority],MATCH($A55,Backlog[Requirement ID],0))),"")
A56: NEW-0100 | B56: =IFERROR(IF(ISBLANK(INDEX(Backlog[Requirement Name],MATCH($A56,Backlog[Requirement ID],0))),"",INDEX(Backlog[Requirement Name],MATCH($A56,Backlog[Requirement ID],0))),"") | C56: =IFERROR(IF(ISBLANK(INDEX(Backlog[Stream],MATCH($A56,Backlog[Requirement ID],0))),"",INDEX(Backlog[Stream],MATCH($A56,Backlog[Requirement ID],0))),"") | D56: =IFERROR(IF(ISBLANK(INDEX(Backlog[Jira Link],MATCH($A56,Backlog[Requirement ID],0))),"",INDEX(Backlog[Jira Link],MATCH($A56,Backlog[Requirement ID],0))),"") | E56: =IFERROR(IF(ISBLANK(INDEX(Backlog[Status],MATCH($A56,Backlog[Requirement ID],0))),"",INDEX(Backlog[Status],MATCH($A56,Backlog[Requirement ID],0))),"") | F56: =IFERROR(IF(ISBLANK(INDEX(SprintPlanning[Sprint],MATCH($A56,SprintPlanning[Requirement ID],0))),"",INDEX(SprintPlanning[Sprint],MATCH($A56,SprintPlanning[Requirement ID],0))),"") | G56: No | J56: =IFERROR(IF(ISBLANK(INDEX(Backlog[Priority],MATCH($A56,Backlog[Requirement ID],0))),"",INDEX(Backlog[Priority],MATCH($A56,Backlog[Requirement ID],0))),"")
A57: NEW-0103 | B57: =IFERROR(IF(ISBLANK(INDEX(Backlog[Requirement Name],MATCH($A57,Backlog[Requirement ID],0))),"",INDEX(Backlog[Requirement Name],MATCH($A57,Backlog[Requirement ID],0))),"") | C57: =IFERROR(IF(ISBLANK(INDEX(Backlog[Stream],MATCH($A57,Backlog[Requirement ID],0))),"",INDEX(Backlog[Stream],MATCH($A57,Backlog[Requirement ID],0))),"") | D57: =IFERROR(IF(ISBLANK(INDEX(Backlog[Jira Link],MATCH($A57,Backlog[Requirement ID],0))),"",INDEX(Backlog[Jira Link],MATCH($A57,Backlog[Requirement ID],0))),"") | E57: =IFERROR(IF(ISBLANK(INDEX(Backlog[Status],MATCH($A57,Backlog[Requirement ID],0))),"",INDEX(Backlog[Status],MATCH($A57,Backlog[Requirement ID],0))),"") | F57: =IFERROR(IF(ISBLANK(INDEX(SprintPlanning[Sprint],MATCH($A57,SprintPlanning[Requirement ID],0))),"",INDEX(SprintPlanning[Sprint],MATCH($A57,SprintPlanning[Requirement ID],0))),"") | G57: Yes | J57: =IFERROR(IF(ISBLANK(INDEX(Backlog[Priority],MATCH($A57,Backlog[Requirement ID],0))),"",INDEX(Backlog[Priority],MATCH($A57,Backlog[Requirement ID],0))),"")
A58: NEW-0104 | B58: =IFERROR(IF(ISBLANK(INDEX(Backlog[Requirement Name],MATCH($A58,Backlog[Requirement ID],0))),"",INDEX(Backlog[Requirement Name],MATCH($A58,Backlog[Requirement ID],0))),"") | C58: =IFERROR(IF(ISBLANK(INDEX(Backlog[Stream],MATCH($A58,Backlog[Requirement ID],0))),"",INDEX(Backlog[Stream],MATCH($A58,Backlog[Requirement ID],0))),"") | D58: =IFERROR(IF(ISBLANK(INDEX(Backlog[Jira Link],MATCH($A58,Backlog[Requirement ID],0))),"",INDEX(Backlog[Jira Link],MATCH($A58,Backlog[Requirement ID],0))),"") | E58: =IFERROR(IF(ISBLANK(INDEX(Backlog[Status],MATCH($A58,Backlog[Requirement ID],0))),"",INDEX(Backlog[Status],MATCH($A58,Backlog[Requirement ID],0))),"") | F58: =IFERROR(IF(ISBLANK(INDEX(SprintPlanning[Sprint],MATCH($A58,SprintPlanning[Requirement ID],0))),"",INDEX(SprintPlanning[Sprint],MATCH($A58,SprintPlanning[Requirement ID],0))),"") | G58: No | J58: =IFERROR(IF(ISBLANK(INDEX(Backlog[Priority],MATCH($A58,Backlog[Requirement ID],0))),"",INDEX(Backlog[Priority],MATCH($A58,Backlog[Requirement ID],0))),"")
A59: NEW-0105 | B59: =IFERROR(IF(ISBLANK(INDEX(Backlog[Requirement Name],MATCH($A59,Backlog[Requirement ID],0))),"",INDEX(Backlog[Requirement Name],MATCH($A59,Backlog[Requirement ID],0))),"") | C59: =IFERROR(IF(ISBLANK(INDEX(Backlog[Stream],MATCH($A59,Backlog[Requirement ID],0))),"",INDEX(Backlog[Stream],MATCH($A59,Backlog[Requirement ID],0))),"") | D59: =IFERROR(IF(ISBLANK(INDEX(Backlog[Jira Link],MATCH($A59,Backlog[Requirement ID],0))),"",INDEX(Backlog[Jira Link],MATCH($A59,Backlog[Requirement ID],0))),"") | E59: =IFERROR(IF(ISBLANK(INDEX(Backlog[Status],MATCH($A59,Backlog[Requirement ID],0))),"",INDEX(Backlog[Status],MATCH($A59,Backlog[Requirement ID],0))),"") | F59: =IFERROR(IF(ISBLANK(INDEX(SprintPlanning[Sprint],MATCH($A59,SprintPlanning[Requirement ID],0))),"",INDEX(SprintPlanning[Sprint],MATCH($A59,SprintPlanning[Requirement ID],0))),"") | G59: No | J59: =IFERROR(IF(ISBLANK(INDEX(Backlog[Priority],MATCH($A59,Backlog[Requirement ID],0))),"",INDEX(Backlog[Priority],MATCH($A59,Backlog[Requirement ID],0))),"")
A60: NEW-0108 | B60: =IFERROR(IF(ISBLANK(INDEX(Backlog[Requirement Name],MATCH($A60,Backlog[Requirement ID],0))),"",INDEX(Backlog[Requirement Name],MATCH($A60,Backlog[Requirement ID],0))),"") | C60: =IFERROR(IF(ISBLANK(INDEX(Backlog[Stream],MATCH($A60,Backlog[Requirement ID],0))),"",INDEX(Backlog[Stream],MATCH($A60,Backlog[Requirement ID],0))),"") | D60: =IFERROR(IF(ISBLANK(INDEX(Backlog[Jira Link],MATCH($A60,Backlog[Requirement ID],0))),"",INDEX(Backlog[Jira Link],MATCH($A60,Backlog[Requirement ID],0))),"") | E60: =IFERROR(IF(ISBLANK(INDEX(Backlog[Status],MATCH($A60,Backlog[Requirement ID],0))),"",INDEX(Backlog[Status],MATCH($A60,Backlog[Requirement ID],0))),"") | F60: =IFERROR(IF(ISBLANK(INDEX(SprintPlanning[Sprint],MATCH($A60,SprintPlanning[Requirement ID],0))),"",INDEX(SprintPlanning[Sprint],MATCH($A60,SprintPlanning[Requirement ID],0))),"") | G60: Yes | J60: =IFERROR(IF(ISBLANK(INDEX(Backlog[Priority],MATCH($A60,Backlog[Requirement ID],0))),"",INDEX(Backlog[Priority],MATCH($A60,Backlog[Requirement ID],0))),"")
A61: NEW-0109 | B61: =IFERROR(IF(ISBLANK(INDEX(Backlog[Requirement Name],MATCH($A61,Backlog[Requirement ID],0))),"",INDEX(Backlog[Requirement Name],MATCH($A61,Backlog[Requirement ID],0))),"") | C61: =IFERROR(IF(ISBLANK(INDEX(Backlog[Stream],MATCH($A61,Backlog[Requirement ID],0))),"",INDEX(Backlog[Stream],MATCH($A61,Backlog[Requirement ID],0))),"") | D61: =IFERROR(IF(ISBLANK(INDEX(Backlog[Jira Link],MATCH($A61,Backlog[Requirement ID],0))),"",INDEX(Backlog[Jira Link],MATCH($A61,Backlog[Requirement ID],0))),"") | E61: =IFERROR(IF(ISBLANK(INDEX(Backlog[Status],MATCH($A61,Backlog[Requirement ID],0))),"",INDEX(Backlog[Status],MATCH($A61,Backlog[Requirement ID],0))),"") | F61: =IFERROR(IF(ISBLANK(INDEX(SprintPlanning[Sprint],MATCH($A61,SprintPlanning[Requirement ID],0))),"",INDEX(SprintPlanning[Sprint],MATCH($A61,SprintPlanning[Requirement ID],0))),"") | G61: Yes | J61: =IFERROR(IF(ISBLANK(INDEX(Backlog[Priority],MATCH($A61,Backlog[Requirement ID],0))),"",INDEX(Backlog[Priority],MATCH($A61,Backlog[Requirement ID],0))),"")
A62: NEW-0111 | B62: =IFERROR(IF(ISBLANK(INDEX(Backlog[Requirement Name],MATCH($A62,Backlog[Requirement ID],0))),"",INDEX(Backlog[Requirement Name],MATCH($A62,Backlog[Requirement ID],0))),"") | C62: =IFERROR(IF(ISBLANK(INDEX(Backlog[Stream],MATCH($A62,Backlog[Requirement ID],0))),"",INDEX(Backlog[Stream],MATCH($A62,Backlog[Requirement ID],0))),"") | D62: =IFERROR(IF(ISBLANK(INDEX(Backlog[Jira Link],MATCH($A62,Backlog[Requirement ID],0))),"",INDEX(Backlog[Jira Link],MATCH($A62,Backlog[Requirement ID],0))),"") | E62: =IFERROR(IF(ISBLANK(INDEX(Backlog[Status],MATCH($A62,Backlog[Requirement ID],0))),"",INDEX(Backlog[Status],MATCH($A62,Backlog[Requirement ID],0))),"") | F62: =IFERROR(IF(ISBLANK(INDEX(SprintPlanning[Sprint],MATCH($A62,SprintPlanning[Requirement ID],0))),"",INDEX(SprintPlanning[Sprint],MATCH($A62,SprintPlanning[Requirement ID],0))),"") | G62: Yes | J62: =IFERROR(IF(ISBLANK(INDEX(Backlog[Priority],MATCH($A62,Backlog[Requirement ID],0))),"",INDEX(Backlog[Priority],MATCH($A62,Backlog[Requirement ID],0))),"")
A63: NEW-0112 | B63: =IFERROR(IF(ISBLANK(INDEX(Backlog[Requirement Name],MATCH($A63,Backlog[Requirement ID],0))),"",INDEX(Backlog[Requirement Name],MATCH($A63,Backlog[Requirement ID],0))),"") | C63: =IFERROR(IF(ISBLANK(INDEX(Backlog[Stream],MATCH($A63,Backlog[Requirement ID],0))),"",INDEX(Backlog[Stream],MATCH($A63,Backlog[Requirement ID],0))),"") | D63: =IFERROR(IF(ISBLANK(INDEX(Backlog[Jira Link],MATCH($A63,Backlog[Requirement ID],0))),"",INDEX(Backlog[Jira Link],MATCH($A63,Backlog[Requirement ID],0))),"") | E63: =IFERROR(IF(ISBLANK(INDEX(Backlog[Status],MATCH($A63,Backlog[Requirement ID],0))),"",INDEX(Backlog[Status],MATCH($A63,Backlog[Requirement ID],0))),"") | F63: =IFERROR(IF(ISBLANK(INDEX(SprintPlanning[Sprint],MATCH($A63,SprintPlanning[Requirement ID],0))),"",INDEX(SprintPlanning[Sprint],MATCH($A63,SprintPlanning[Requirement ID],0))),"") | G63: No | J63: =IFERROR(IF(ISBLANK(INDEX(Backlog[Priority],MATCH($A63,Backlog[Requirement ID],0))),"",INDEX(Backlog[Priority],MATCH($A63,Backlog[Requirement ID],0))),"")
A64: NEW-0113 | B64: =IFERROR(IF(ISBLANK(INDEX(Backlog[Requirement Name],MATCH($A64,Backlog[Requirement ID],0))),"",INDEX(Backlog[Requirement Name],MATCH($A64,Backlog[Requirement ID],0))),"") | C64: =IFERROR(IF(ISBLANK(INDEX(Backlog[Stream],MATCH($A64,Backlog[Requirement ID],0))),"",INDEX(Backlog[Stream],MATCH($A64,Backlog[Requirement ID],0))),"") | D64: =IFERROR(IF(ISBLANK(INDEX(Backlog[Jira Link],MATCH($A64,Backlog[Requirement ID],0))),"",INDEX(Backlog[Jira Link],MATCH($A64,Backlog[Requirement ID],0))),"") | E64: =IFERROR(IF(ISBLANK(INDEX(Backlog[Status],MATCH($A64,Backlog[Requirement ID],0))),"",INDEX(Backlog[Status],MATCH($A64,Backlog[Requirement ID],0))),"") | F64: =IFERROR(IF(ISBLANK(INDEX(SprintPlanning[Sprint],MATCH($A64,SprintPlanning[Requirement ID],0))),"",INDEX(SprintPlanning[Sprint],MATCH($A64,SprintPlanning[Requirement ID],0))),"") | G64: No | J64: =IFERROR(IF(ISBLANK(INDEX(Backlog[Priority],MATCH($A64,Backlog[Requirement ID],0))),"",INDEX(Backlog[Priority],MATCH($A64,Backlog[Requirement ID],0))),"")
A65: NEW-0120 | B65: =IFERROR(IF(ISBLANK(INDEX(Backlog[Requirement Name],MATCH($A65,Backlog[Requirement ID],0))),"",INDEX(Backlog[Requirement Name],MATCH($A65,Backlog[Requirement ID],0))),"") | C65: =IFERROR(IF(ISBLANK(INDEX(Backlog[Stream],MATCH($A65,Backlog[Requirement ID],0))),"",INDEX(Backlog[Stream],MATCH($A65,Backlog[Requirement ID],0))),"") | D65: =IFERROR(IF(ISBLANK(INDEX(Backlog[Jira Link],MATCH($A65,Backlog[Requirement ID],0))),"",INDEX(Backlog[Jira Link],MATCH($A65,Backlog[Requirement ID],0))),"") | E65: =IFERROR(IF(ISBLANK(INDEX(Backlog[Status],MATCH($A65,Backlog[Requirement ID],0))),"",INDEX(Backlog[Status],MATCH($A65,Backlog[Requirement ID],0))),"") | F65: =IFERROR(IF(ISBLANK(INDEX(SprintPlanning[Sprint],MATCH($A65,SprintPlanning[Requirement ID],0))),"",INDEX(SprintPlanning[Sprint],MATCH($A65,SprintPlanning[Requirement ID],0))),"") | G65: Yes | J65: =IFERROR(IF(ISBLANK(INDEX(Backlog[Priority],MATCH($A65,Backlog[Requirement ID],0))),"",INDEX(Backlog[Priority],MATCH($A65,Backlog[Requirement ID],0))),"")
A66: NEW-0121 | B66: =IFERROR(IF(ISBLANK(INDEX(Backlog[Requirement Name],MATCH($A66,Backlog[Requirement ID],0))),"",INDEX(Backlog[Requirement Name],MATCH($A66,Backlog[Requirement ID],0))),"") | C66: =IFERROR(IF(ISBLANK(INDEX(Backlog[Stream],MATCH($A66,Backlog[Requirement ID],0))),"",INDEX(Backlog[Stream],MATCH($A66,Backlog[Requirement ID],0))),"") | D66: =IFERROR(IF(ISBLANK(INDEX(Backlog[Jira Link],MATCH($A66,Backlog[Requirement ID],0))),"",INDEX(Backlog[Jira Link],MATCH($A66,Backlog[Requirement ID],0))),"") | E66: =IFERROR(IF(ISBLANK(INDEX(Backlog[Status],MATCH($A66,Backlog[Requirement ID],0))),"",INDEX(Backlog[Status],MATCH($A66,Backlog[Requirement ID],0))),"") | F66: =IFERROR(IF(ISBLANK(INDEX(SprintPlanning[Sprint],MATCH($A66,SprintPlanning[Requirement ID],0))),"",INDEX(SprintPlanning[Sprint],MATCH($A66,SprintPlanning[Requirement ID],0))),"") | G66: No | J66: =IFERROR(IF(ISBLANK(INDEX(Backlog[Priority],MATCH($A66,Backlog[Requirement ID],0))),"",INDEX(Backlog[Priority],MATCH($A66,Backlog[Requirement ID],0))),"")
A67: NEW-0122 | B67: =IFERROR(IF(ISBLANK(INDEX(Backlog[Requirement Name],MATCH($A67,Backlog[Requirement ID],0))),"",INDEX(Backlog[Requirement Name],MATCH($A67,Backlog[Requirement ID],0))),"") | C67: =IFERROR(IF(ISBLANK(INDEX(Backlog[Stream],MATCH($A67,Backlog[Requirement ID],0))),"",INDEX(Backlog[Stream],MATCH($A67,Backlog[Requirement ID],0))),"") | D67: =IFERROR(IF(ISBLANK(INDEX(Backlog[Jira Link],MATCH($A67,Backlog[Requirement ID],0))),"",INDEX(Backlog[Jira Link],MATCH($A67,Backlog[Requirement ID],0))),"") | E67: =IFERROR(IF(ISBLANK(INDEX(Backlog[Status],MATCH($A67,Backlog[Requirement ID],0))),"",INDEX(Backlog[Status],MATCH($A67,Backlog[Requirement ID],0))),"") | F67: =IFERROR(IF(ISBLANK(INDEX(SprintPlanning[Sprint],MATCH($A67,SprintPlanning[Requirement ID],0))),"",INDEX(SprintPlanning[Sprint],MATCH($A67,SprintPlanning[Requirement ID],0))),"") | G67: No | J67: =IFERROR(IF(ISBLANK(INDEX(Backlog[Priority],MATCH($A67,Backlog[Requirement ID],0))),"",INDEX(Backlog[Priority],MATCH($A67,Backlog[Requirement ID],0))),"")
A68: NEW-0123 | B68: =IFERROR(IF(ISBLANK(INDEX(Backlog[Requirement Name],MATCH($A68,Backlog[Requirement ID],0))),"",INDEX(Backlog[Requirement Name],MATCH($A68,Backlog[Requirement ID],0))),"") | C68: =IFERROR(IF(ISBLANK(INDEX(Backlog[Stream],MATCH($A68,Backlog[Requirement ID],0))),"",INDEX(Backlog[Stream],MATCH($A68,Backlog[Requirement ID],0))),"") | D68: =IFERROR(IF(ISBLANK(INDEX(Backlog[Jira Link],MATCH($A68,Backlog[Requirement ID],0))),"",INDEX(Backlog[Jira Link],MATCH($A68,Backlog[Requirement ID],0))),"") | E68: =IFERROR(IF(ISBLANK(INDEX(Backlog[Status],MATCH($A68,Backlog[Requirement ID],0))),"",INDEX(Backlog[Status],MATCH($A68,Backlog[Requirement ID],0))),"") | F68: =IFERROR(IF(ISBLANK(INDEX(SprintPlanning[Sprint],MATCH($A68,SprintPlanning[Requirement ID],0))),"",INDEX(SprintPlanning[Sprint],MATCH($A68,SprintPlanning[Requirement ID],0))),"") | G68: No | J68: =IFERROR(IF(ISBLANK(INDEX(Backlog[Priority],MATCH($A68,Backlog[Requirement ID],0))),"",INDEX(Backlog[Priority],MATCH($A68,Backlog[Requirement ID],0))),"")
A69: NEW-0127 | B69: =IFERROR(IF(ISBLANK(INDEX(Backlog[Requirement Name],MATCH($A69,Backlog[Requirement ID],0))),"",INDEX(Backlog[Requirement Name],MATCH($A69,Backlog[Requirement ID],0))),"") | C69: =IFERROR(IF(ISBLANK(INDEX(Backlog[Stream],MATCH($A69,Backlog[Requirement ID],0))),"",INDEX(Backlog[Stream],MATCH($A69,Backlog[Requirement ID],0))),"") | D69: =IFERROR(IF(ISBLANK(INDEX(Backlog[Jira Link],MATCH($A69,Backlog[Requirement ID],0))),"",INDEX(Backlog[Jira Link],MATCH($A69,Backlog[Requirement ID],0))),"") | E69: =IFERROR(IF(ISBLANK(INDEX(Backlog[Status],MATCH($A69,Backlog[Requirement ID],0))),"",INDEX(Backlog[Status],MATCH($A69,Backlog[Requirement ID],0))),"") | F69: =IFERROR(IF(ISBLANK(INDEX(SprintPlanning[Sprint],MATCH($A69,SprintPlanning[Requirement ID],0))),"",INDEX(SprintPlanning[Sprint],MATCH($A69,SprintPlanning[Requirement ID],0))),"") | J69: =IFERROR(IF(ISBLANK(INDEX(Backlog[Priority],MATCH($A69,Backlog[Requirement ID],0))),"",INDEX(Backlog[Priority],MATCH($A69,Backlog[Requirement ID],0))),"")
A70: NEW-0131 | B70: =IFERROR(IF(ISBLANK(INDEX(Backlog[Requirement Name],MATCH($A70,Backlog[Requirement ID],0))),"",INDEX(Backlog[Requirement Name],MATCH($A70,Backlog[Requirement ID],0))),"") | C70: =IFERROR(IF(ISBLANK(INDEX(Backlog[Stream],MATCH($A70,Backlog[Requirement ID],0))),"",INDEX(Backlog[Stream],MATCH($A70,Backlog[Requirement ID],0))),"") | D70: =IFERROR(IF(ISBLANK(INDEX(Backlog[Jira Link],MATCH($A70,Backlog[Requirement ID],0))),"",INDEX(Backlog[Jira Link],MATCH($A70,Backlog[Requirement ID],0))),"") | E70: =IFERROR(IF(ISBLANK(INDEX(Backlog[Status],MATCH($A70,Backlog[Requirement ID],0))),"",INDEX(Backlog[Status],MATCH($A70,Backlog[Requirement ID],0))),"") | F70: =IFERROR(IF(ISBLANK(INDEX(SprintPlanning[Sprint],MATCH($A70,SprintPlanning[Requirement ID],0))),"",INDEX(SprintPlanning[Sprint],MATCH($A70,SprintPlanning[Requirement ID],0))),"") | J70: =IFERROR(IF(ISBLANK(INDEX(Backlog[Priority],MATCH($A70,Backlog[Requirement ID],0))),"",INDEX(Backlog[Priority],MATCH($A70,Backlog[Requirement ID],0))),"")
A71: NEW-0133 | B71: =IFERROR(IF(ISBLANK(INDEX(Backlog[Requirement Name],MATCH($A71,Backlog[Requirement ID],0))),"",INDEX(Backlog[Requirement Name],MATCH($A71,Backlog[Requirement ID],0))),"") | C71: =IFERROR(IF(ISBLANK(INDEX(Backlog[Stream],MATCH($A71,Backlog[Requirement ID],0))),"",INDEX(Backlog[Stream],MATCH($A71,Backlog[Requirement ID],0))),"") | D71: =IFERROR(IF(ISBLANK(INDEX(Backlog[Jira Link],MATCH($A71,Backlog[Requirement ID],0))),"",INDEX(Backlog[Jira Link],MATCH($A71,Backlog[Requirement ID],0))),"") | E71: =IFERROR(IF(ISBLANK(INDEX(Backlog[Status],MATCH($A71,Backlog[Requirement ID],0))),"",INDEX(Backlog[Status],MATCH($A71,Backlog[Requirement ID],0))),"") | F71: =IFERROR(IF(ISBLANK(INDEX(SprintPlanning[Sprint],MATCH($A71,SprintPlanning[Requirement ID],0))),"",INDEX(SprintPlanning[Sprint],MATCH($A71,SprintPlanning[Requirement ID],0))),"") | G71: Yes | J71: =IFERROR(IF(ISBLANK(INDEX(Backlog[Priority],MATCH($A71,Backlog[Requirement ID],0))),"",INDEX(Backlog[Priority],MATCH($A71,Backlog[Requirement ID],0))),"")
A72: NEW-0135 | B72: =IFERROR(IF(ISBLANK(INDEX(Backlog[Requirement Name],MATCH($A72,Backlog[Requirement ID],0))),"",INDEX(Backlog[Requirement Name],MATCH($A72,Backlog[Requirement ID],0))),"") | C72: =IFERROR(IF(ISBLANK(INDEX(Backlog[Stream],MATCH($A72,Backlog[Requirement ID],0))),"",INDEX(Backlog[Stream],MATCH($A72,Backlog[Requirement ID],0))),"") | D72: =IFERROR(IF(ISBLANK(INDEX(Backlog[Jira Link],MATCH($A72,Backlog[Requirement ID],0))),"",INDEX(Backlog[Jira Link],MATCH($A72,Backlog[Requirement ID],0))),"") | E72: =IFERROR(IF(ISBLANK(INDEX(Backlog[Status],MATCH($A72,Backlog[Requirement ID],0))),"",INDEX(Backlog[Status],MATCH($A72,Backlog[Requirement ID],0))),"") | F72: =IFERROR(IF(ISBLANK(INDEX(SprintPlanning[Sprint],MATCH($A72,SprintPlanning[Requirement ID],0))),"",INDEX(SprintPlanning[Sprint],MATCH($A72,SprintPlanning[Requirement ID],0))),"") | G72: Yes | J72: =IFERROR(IF(ISBLANK(INDEX(Backlog[Priority],MATCH($A72,Backlog[Requirement ID],0))),"",INDEX(Backlog[Priority],MATCH($A72,Backlog[Requirement ID],0))),"")
