Workbook

Sheet README
B1: EINT MuleSoft Backlog Tracker — How This Works
A3: Automation: Auto-Archive on DONE | B3: Replaces: MuleSoft Team - Planning.xlsx and Requirements Traceability Matrix - EINT Mulesoft 2026.xlsx
A4: When an item Status is set to DONE in Backlog with a real Sprint assigned (1-16), the autoArchive automation:
A5: 1. Appends it to the matching Quarter tab (Sprint 1-4 → Q1 Backlog Report, etc.) | B5: The golden rule: every field has exactly one home.
A6: 2. Freezes formula-driven fields in the Release row to literal values | B6: Each requirement is one row, tracked by its Requirement ID across every tab below. Each field (Priority, Sprint, Dependencies, Release, etc.) is only ever typed into ONE tab — the tab owned by the role responsible for it. Every other tab shows that same field automatically, pulled live from wherever it was entered. If you change it in its home tab, it updates everywhere else immediately. Nobody should ever need to copy a value between tabs by hand.
A7: 3. Removes it from the 5 working sheets (Backlog, Sprint Planning, RTM, API Design Planning, Release)
B8: Colour legend
A9: NOTE: Items with Status=DONE but no sprint (or "To Plan") are skipped—they need a real sprint first. | B9: Text is plain black everywhere. Row shading instead shows which Stream an item belongs to (applied automatically via conditional formatting, so it updates itself as Stream values change):
B10: US
A11: Setup: See the "Workflows" sheet for step-by-step instructions to upload the Office Script and create the Power Automate flow. | B11: MyMSC
B12: Rollout / MVP Rollout
B13: Backlog / Growth
B14: Tech Enhancements
B15: PI11, PI12, or any other PI-specific stream
B16: Cross, or any other stream not listed above -- no shading (white/default)
B17: Who's allowed to edit which field is documented in the ownership table below, not by colour anymore.
B19: Requirement ID convention
B20: Use the Jira key (e.g. INT-171) as the Requirement ID whenever a Jira ticket already exists. Anyone can also add a future item straight to the Backlog tab with no Jira ticket at all — give it a temporary ID in the form NEW-0001, NEW-0002, etc. IMPORTANT: this Requirement ID never changes afterwards, even once a real Jira ticket exists for it — every other tab is joined to this ID, so swapping it would break those links. When the item is ready to become a real Jira ticket, set 'Create Jira Ticket?' to Yes on the Backlog tab; the returned Jira key is written into the separate Jira Key / Jira Link columns alongside the ID, not in place of it.
B22: Tab ownership — who edits what
B23: Tab | C23: Owner | D23: Types here (input) | E23: Shown automatically (pulled)
B24: Backlog | C24: Anyone (entry point) | D24: Requirement Name, Type, Stream, Status, Date Added, Create Jira Ticket?, Jira Key | E24: Jira Link, Priority, Sprint, Release
B25: API Design Planning | C25: API Design Lead | D25: RAML Required, RAML Delivery Date, Assignee, Priority, Design Status, Handover | E25: Requirement Name, Stream, Jira Link, Status, Sprint
B26: RTM | C26: BA | D26: Predecessor, Successor, Dependency Status, Notes | E26: Requirement Name, Stream, Jira Link, Status, Priority, Sprint
B27: Sprint Planning | C27: BA / PO / SM | D27: Sprint, HLE | E27: Requirement Name, Stream, Priority, Status
B28: Roadmap | C28: Nobody — all view | D28: (fully automatic) | E28: Stream x Sprint HLE grid
B29: Release | C29: DM / SM | D29: Release | E29: Requirement Name, Stream, Sprint, Status, Priority, HLE
B31: Current status
B32: Items from MuleSoft Team - Planning.xlsx and the Requirements Traceability Matrix have been migrated. All working tabs (Backlog, Sprint Planning, RTM, API Design Planning, Release, Roadmap) contain live data. Archived items from 2026 are in the Q1–Q3 Backlog Report tabs. The Jira and Trello integrations listed below (items 1–5) are still planned for a future phase.
B33: 1. Jira (labelled ticket) -> auto-creates a Backlog row with Jira Key/Link filled in.
B34: 2. Any new Backlog row (Jira-sourced or typed straight in with no Jira ticket) -> auto-creates a Trello card.
B35: 3. Sprint changed for an item -> updates the sprint label on its Trello card.
B36: 4. 'Create Jira Ticket?' set to Yes on a manually-added row -> creates the Jira issue and writes the key back into Jira Key/Jira Link, then flips the flag to Created.
B37: 5. Scheduled refresh of the RTM Dependency Status column from the live status of the Predecessor/Successor Jira key.
B39: Until items 1–5 are wired up, fill in Jira Key, Predecessor/Successor, and Dependency Status manually.
B41: Sprint Planning sort order
B42: Sprint Planning is kept sorted ascending by Sprint (lowest in-scope sprint first, unassigned/'To Plan' last), using a hidden 'Sort Key' column (H) that converts the Sprint text to a number. If you add new rows and want to re-sort, select the table and use Data > Sort by column H — don't unhide/delete that column.
B44: Release tab population
B45: The Release tab lists every item that has a real Sprint assigned in Sprint Planning (not blank/'To Plan') — once an item gets a sprint for the first time, add its Requirement ID to the Release tab so DM/SM can assign it a Release. This mirrors how RTM/Sprint Planning/API Design Planning already work: copy the ID over when the item reaches that stage.
... B49: Sprint → Quarter mapping: Sprint 1–4 → Q1 · Sprint 5–8 → Q2 · Sprint 9–12 → Q3 · Sprint 13–16 → Q4. Update the mapping in autoArchive.ts when sprints roll into 2027.

Sheet Backlog
A1: Requirement ID | B1: Requirement Name | C1: Type | D1: Stream | E1: Stream Owner | F1: Status | G1: Priority | H1: Planned Delivery | I1: Sprint | J1: HLE | K1: Release | L1: Date Added | M1: Create Jira Ticket? | N1: Jira Link | O1: Notes | P1: ID Number | Q1: Frozen ID
A2: =IF(AND(B2="",C2="",D2="",E2="",F2="",G2="",H2="",J2="",L2="",M2="",N2=""),"",Q2) -> NEW-0267 | B2: Outbound leads - Abandoned Cart - Replacement of Salescycle | C2: TBC | D2: US | E2: MA | F2: ON HOLD | G2: Medium | I2: =IF($A2="","",IFERROR(IF(ISBLANK(INDEX(SprintPlanning[Sprint],MATCH($A2,SprintPlanning[Requirement ID],0))),"To Plan",INDEX(SprintPlanning[Sprint],MATCH($A2,SprintPlanning[Requirement ID],0))),"To Plan")) -> To Plan | K2: =IFERROR(IF(ISBLANK(INDEX(Release[Release],MATCH($A2,Release[Requirement ID],0))),"",INDEX(Release[Release],MATCH($A2,Release[Requirement ID],0))),"") | L2: 46232 | P2: =IFERROR(VALUE(MID($A2,5,4)),0) -> 267 | Q2: NEW-0267
A3: =IF(AND(B3="",C3="",D3="",E3="",F3="",G3="",H3="",J3="",L3="",M3="",N3=""),"",Q3) -> NEW-0057 | B3: API Prod Configurations - Attentive / Webforms | C3: Config | D3: US | E3: B2CW | F3: IN PROGRESS | G3: High | I3: =IF($A3="","",IFERROR(IF(ISBLANK(INDEX(SprintPlanning[Sprint],MATCH($A3,SprintPlanning[Requirement ID],0))),"To Plan",INDEX(SprintPlanning[Sprint],MATCH($A3,SprintPlanning[Requirement ID],0))),"To Plan")) -> Sprint 10 | J3: 8 | K3: =IFERROR(IF(ISBLANK(INDEX(Release[Release],MATCH($A3,Release[Requirement ID],0))),"",INDEX(Release[Release],MATCH($A3,Release[Requirement ID],0))),"") -> Release 19 | L3: 46226 | M3: Created | N3: https://smartship.atlassian.net/browse/MDTTPU-14019 | P3: =IFERROR(VALUE(MID($A3,5,4)),0) -> 57 | Q3: NEW-0057
A4: =IF(AND(B4="",C4="",D4="",E4="",F4="",G4="",H4="",J4="",L4="",M4="",N4=""),"",Q4) -> NEW-0058 | B4: CR - Attentive Error Scenarios INT 175 | C4: CR | D4: US | E4: MA | F4: IN PROGRESS | G4: Medium | I4: =IF($A4="","",IFERROR(IF(ISBLANK(INDEX(SprintPlanning[Sprint],MATCH($A4,SprintPlanning[Requirement ID],0))),"To Plan",INDEX(SprintPlanning[Sprint],MATCH($A4,SprintPlanning[Requirement ID],0))),"To Plan")) -> Sprint 10 | J4: 5 | K4: =IFERROR(IF(ISBLANK(INDEX(Release[Release],MATCH($A4,Release[Requirement ID],0))),"",INDEX(Release[Release],MATCH($A4,Release[Requirement ID],0))),"") -> Release 19 | L4: 46226 | M4: Created | N4: https://smartship.atlassian.net/browse/MDTTPU-13413 | P4: =IFERROR(VALUE(MID($A4,5,4)),0) -> 58 | Q4: NEW-0058
A5: =IF(AND(B5="",C5="",D5="",E5="",F5="",G5="",H5="",J5="",L5="",M5="",N5=""),"",Q5) -> NEW-0060 | B5: US Configuration myMSC - Production | C5: Config | D5: US | E5: B2CW | F5: IN PROGRESS | G5: High | I5: =IF($A5="","",IFERROR(IF(ISBLANK(INDEX(SprintPlanning[Sprint],MATCH($A5,SprintPlanning[Requirement ID],0))),"To Plan",INDEX(SprintPlanning[Sprint],MATCH($A5,SprintPlanning[Requirement ID],0))),"To Plan")) -> Sprint 10 | J5: 8 | K5: =IFERROR(IF(ISBLANK(INDEX(Release[Release],MATCH($A5,Release[Requirement ID],0))),"",INDEX(Release[Release],MATCH($A5,Release[Requirement ID],0))),"") -> Release 19 | L5: 46226 | M5: Created | N5: https://smartship.atlassian.net/browse/MDTTPU-14018 | P5: =IFERROR(VALUE(MID($A5,5,4)),0) -> 60 | Q5: NEW-0060
A6: =IF(AND(B6="",C6="",D6="",E6="",F6="",G6="",H6="",J6="",L6="",M6="",N6=""),"",Q6) -> NEW-0061 | B6: Load Test + Performance Enhancements - Part 1 | C6: Tech Task | D6: US | E6: ALL | F6: IN PROGRESS | G6: High | I6: =IF($A6="","",IFERROR(IF(ISBLANK(INDEX(SprintPlanning[Sprint],MATCH($A6,SprintPlanning[Requirement ID],0))),"To Plan",INDEX(SprintPlanning[Sprint],MATCH($A6,SprintPlanning[Requirement ID],0))),"To Plan")) -> Sprint 10 | J6: 21 | K6: =IFERROR(IF(ISBLANK(INDEX(Release[Release],MATCH($A6,Release[Requirement ID],0))),"",INDEX(Release[Release],MATCH($A6,Release[Requirement ID],0))),"") -> Release 19 | L6: 46226 | M6: Created | N6: https://smartship.atlassian.net/browse/MDTTPU-15260 | P6: =IFERROR(VALUE(MID($A6,5,4)),0) -> 61 | Q6: NEW-0061
A7: =IF(AND(B7="",C7="",D7="",E7="",F7="",G7="",H7="",J7="",L7="",M7="",N7=""),"",Q7) -> NEW-0071 | B7: E2E Ticket Support - FAT and Canary Tests | C7: Tech Task | D7: US | E7: ALL | F7: IN PROGRESS | G7: High | I7: =IF($A7="","",IFERROR(IF(ISBLANK(INDEX(SprintPlanning[Sprint],MATCH($A7,SprintPlanning[Requirement ID],0))),"To Plan",INDEX(SprintPlanning[Sprint],MATCH($A7,SprintPlanning[Requirement ID],0))),"To Plan")) -> Sprint 10 | J7: 13 | K7: =IFERROR(IF(ISBLANK(INDEX(Release[Release],MATCH($A7,Release[Requirement ID],0))),"",INDEX(Release[Release],MATCH($A7,Release[Requirement ID],0))),"") -> Release 19 | L7: 46226 | M7: Created | N7: https://smartship.atlassian.net/browse/DTTP25-41779 | P7: =IFERROR(VALUE(MID($A7,5,4)),0) -> 71 | Q7: NEW-0071
A8: =IF(AND(B8="",C8="",D8="",E8="",F8="",G8="",H8="",J8="",L8="",M8="",N8=""),"",Q8) -> NEW-0275 | B8: [EINT] [Tech Task] INT172 INT174 - Attentive Error Scenarios | C8: Tech Task | D8: US | E8: MA | F8: IN PROGRESS | G8: Medium | I8: =IF($A8="","",IFERROR(IF(ISBLANK(INDEX(SprintPlanning[Sprint],MATCH($A8,SprintPlanning[Requirement ID],0))),"To Plan",INDEX(SprintPlanning[Sprint],MATCH($A8,SprintPlanning[Requirement ID],0))),"To Plan")) -> Sprint 10 | J8: 5 | K8: =IFERROR(IF(ISBLANK(INDEX(Release[Release],MATCH($A8,Release[Requirement ID],0))),"",INDEX(Release[Release],MATCH($A8,Release[Requirement ID],0))),"") -> Release 19 | L8: 46232 | M8: Created | N8: https://smartship.atlassian.net/browse/MDTTPU-13796 | P8: =IFERROR(VALUE(MID($A8,5,4)),0) -> 275 | Q8: NEW-0275
A9: =IF(AND(B9="",C9="",D9="",E9="",F9="",G9="",H9="",J9="",L9="",M9="",N9=""),"",Q9) -> NEW-0368 | B9: MyMSC US | [INT112][INT137][INT140][INT146][INT153][INT154][INT188] Add per-country/language MyMSC campaign config check to skip optional marketing automation calls | C9: CR | D9: Growth | E9: MA | F9: IN PROGRESS | G9: High | I9: =IF($A9="","",IFERROR(IF(ISBLANK(INDEX(SprintPlanning[Sprint],MATCH($A9,SprintPlanning[Requirement ID],0))),"To Plan",INDEX(SprintPlanning[Sprint],MATCH($A9,SprintPlanning[Requirement ID],0))),"To Plan")) -> Sprint 10 | J9: 8 | K9: =IFERROR(IF(ISBLANK(INDEX(Release[Release],MATCH($A9,Release[Requirement ID],0))),"",INDEX(Release[Release],MATCH($A9,Release[Requirement ID],0))),"") -> Release 19 | L9: 46232 | M9: Created | N9: https://smartship.atlassian.net/browse/MDTTPU-14929 | P9: =IFERROR(VALUE(MID($A9,5,4)),0) -> 368 | Q9: NEW-0368
A10: =IF(AND(B10="",C10="",D10="",E10="",F10="",G10="",H10="",J10="",L10="",M10="",N10=""),"",Q10) -> NEW-0389 | B10: [DTTP] Implementation of Online Post-Cruise Complaint Form – Salesforce Integration_EA | C10: CR | D10: PI10 | E10: B2CW | F10: IN PROGRESS | G10: Medium | I10: =IF($A10="","",IFERROR(IF(ISBLANK(INDEX(SprintPlanning[Sprint],MATCH($A10,SprintPlanning[Requirement ID],0))),"To Plan",INDEX(SprintPlanning[Sprint],MATCH($A10,SprintPlanning[Requirement ID],0))),"To Plan")) -> Sprint 10 | J10: 8 | K10: =IFERROR(IF(ISBLANK(INDEX(Release[Release],MATCH($A10,Release[Requirement ID],0))),"",INDEX(Release[Release],MATCH($A10,Release[Requirement ID],0))),"") | L10: 46232 | M10: Created | N10: https://smartship.atlassian.net/browse/DTTP25-40322 | P10: =IFERROR(VALUE(MID($A10,5,4)),0) -> 389 | Q10: NEW-0389
A11: =IF(AND(B11="",C11="",D11="",E11="",F11="",G11="",H11="",J11="",L11="",M11="",N11=""),"",Q11) -> NEW-0408 | B11: US Growth - B2CW Payment billing data/ US Release ACS Check - Part 1 (Adding the new fields to INT007, INT140, INT146) | C11: CR | D11: Growth | E11: B2CW | F11: NEW | G11: High | H11: Q3 2026 | I11: =IF($A11="","",IFERROR(IF(ISBLANK(INDEX(SprintPlanning[Sprint],MATCH($A11,SprintPlanning[Requirement ID],0))),"To Plan",INDEX(SprintPlanning[Sprint],MATCH($A11,SprintPlanning[Requirement ID],0))),"To Plan")) -> Sprint 10 | J11: 5 | K11: =IFERROR(IF(ISBLANK(INDEX(Release[Release],MATCH($A11,Release[Requirement ID],0))),"",INDEX(Release[Release],MATCH($A11,Release[Requirement ID],0))),"") | L11: 46237 | M11: Created | N11: https://smartship.atlassian.net/browse/MDTTPU-15252 | P11: =IFERROR(VALUE(MID($A11,5,4)),0) -> 408 | Q11: NEW-0408
A12: =IF(AND(B12="",C12="",D12="",E12="",F12="",G12="",H12="",J12="",L12="",M12="",N12=""),"",Q12) -> NEW-0411 | B12: Load Test Perf - Support & Analysis | C12: Tech Task | D12: US | E12: ALL | F12: IN PROGRESS | G12: High | I12: =IF($A12="","",IFERROR(IF(ISBLANK(INDEX(SprintPlanning[Sprint],MATCH($A12,SprintPlanning[Requirement ID],0))),"To Plan",INDEX(SprintPlanning[Sprint],MATCH($A12,SprintPlanning[Requirement ID],0))),"To Plan")) -> Sprint 10 | J12: 21 | K12: =IFERROR(IF(ISBLANK(INDEX(Release[Release],MATCH($A12,Release[Requirement ID],0))),"",INDEX(Release[Release],MATCH($A12,Release[Requirement ID],0))),"") | L12: 46237 | M12: Created | N12: https://smartship.atlassian.net/browse/MDTTPU-15252 | P12: =IFERROR(VALUE(MID($A12,5,4)),0) -> 411 | Q12: NEW-0411
A13: =IF(AND(B13="",C13="",D13="",E13="",F13="",G13="",H13="",J13="",L13="",M13="",N13=""),"",Q13) -> NEW-0412 | B13: US 0.1 Release Preparation - Aug 24 | C13: Tech Task | D13: Cross | E13: ALL | F13: IN PROGRESS | G13: High | I13: =IF($A13="","",IFERROR(IF(ISBLANK(INDEX(SprintPlanning[Sprint],MATCH($A13,SprintPlanning[Requirement ID],0))),"To Plan",INDEX(SprintPlanning[Sprint],MATCH($A13,SprintPlanning[Requirement ID],0))),"To Plan")) -> Sprint 10 | J13: 13 | K13: =IFERROR(IF(ISBLANK(INDEX(Release[Release],MATCH($A13,Release[Requirement ID],0))),"",INDEX(Release[Release],MATCH($A13,Release[Requirement ID],0))),"") | L13: 46237 | M13: Created | N13: https://smartship.atlassian.net/browse/MDTTPU-15262 | P13: =IFERROR(VALUE(MID($A13,5,4)),0) -> 412 | Q13: NEW-0412
A14: =IF(AND(B14="",C14="",D14="",E14="",F14="",G14="",H14="",J14="",L14="",M14="",N14=""),"",Q14) -> NEW-0064 | B14: ZAF Rollout - Market Configurations in CHAIN1 & CHAIN2 and PROD | C14: Config | D14: MVP Rollout | E14: B2CW | F14: NEW | G14: Medium | I14: =IF($A14="","",IFERROR(IF(ISBLANK(INDEX(SprintPlanning[Sprint],MATCH($A14,SprintPlanning[Requirement ID],0))),"To Plan",INDEX(SprintPlanning[Sprint],MATCH($A14,SprintPlanning[Requirement ID],0))),"To Plan")) -> Sprint 11 | J14: 8 | K14: =IFERROR(IF(ISBLANK(INDEX(Release[Release],MATCH($A14,Release[Requirement ID],0))),"",INDEX(Release[Release],MATCH($A14,Release[Requirement ID],0))),"") | L14: 46226 | M14: Created | N14: https://smartship.atlassian.net/browse/DTTP25-41351 | P14: =IFERROR(VALUE(MID($A14,5,4)),0) -> 64 | Q14: NEW-0064
A15: =IF(AND(B15="",C15="",D15="",E15="",F15="",G15="",H15="",J15="",L15="",M15="",N15=""),"",Q15) -> NEW-0065 | B15: ZAFRollout - Market Configurations in Production | C15: Config | D15: MVP Rollout | E15: B2CW | F15: NA | G15: Medium | I15: =IF($A15="","",IFERROR(IF(ISBLANK(INDEX(SprintPlanning[Sprint],MATCH($A15,SprintPlanning[Requirement ID],0))),"To Plan",INDEX(SprintPlanning[Sprint],MATCH($A15,SprintPlanning[Requirement ID],0))),"To Plan")) -> To Plan | J15: 8 | K15: =IFERROR(IF(ISBLANK(INDEX(Release[Release],MATCH($A15,Release[Requirement ID],0))),"",INDEX(Release[Release],MATCH($A15,Release[Requirement ID],0))),"") | L15: 46226 | M15: Created | N15: https://smartship.atlassian.net/browse/DTTP25-41351 | P15: =IFERROR(VALUE(MID($A15,5,4)),0) -> 65 | Q15: NEW-0065
A16: =IF(AND(B16="",C16="",D16="",E16="",F16="",G16="",H16="",J16="",L16="",M16="",N16=""),"",Q16) -> NEW-0075 | B16: PI11-13 [CRM] [INTP-25] CRM Dependency - Marketing Automation - Calculated fields Booking B2B/B2C | C16: CR | D16: PI11 | E16: MA | F16: NEW | G16: Medium | I16: =IF($A16="","",IFERROR(IF(ISBLANK(INDEX(SprintPlanning[Sprint],MATCH($A16,SprintPlanning[Requirement ID],0))),"To Plan",INDEX(SprintPlanning[Sprint],MATCH($A16,SprintPlanning[Requirement ID],0))),"To Plan")) -> Sprint 12 | J16: 13 | K16: =IFERROR(IF(ISBLANK(INDEX(Release[Release],MATCH($A16,Release[Requirement ID],0))),"",INDEX(Release[Release],MATCH($A16,Release[Requirement ID],0))),"") | L16: 46226 | M16: Created | N16: https://smartship.atlassian.net/browse/DTTP25-41935 | P16: =IFERROR(VALUE(MID($A16,5,4)),0) -> 75 | Q16: NEW-0075
A17: =IF(AND(B17="",C17="",D17="",E17="",F17="",G17="",H17="",J17="",L17="",M17="",N17=""),"",Q17) -> NEW-0076 | B17: PI11-15 [CRM] [EA-1662] CRM Dependency - Lead Management - Hold option additional event fields in CDP | C17: CR | D17: PI11 | E17: MA | F17: NEW | G17: Medium | I17: =IF($A17="","",IFERROR(IF(ISBLANK(INDEX(SprintPlanning[Sprint],MATCH($A17,SprintPlanning[Requirement ID],0))),"To Plan",INDEX(SprintPlanning[Sprint],MATCH($A17,SprintPlanning[Requirement ID],0))),"To Plan")) -> Sprint 12 | J17: 13 | K17: =IFERROR(IF(ISBLANK(INDEX(Release[Release],MATCH($A17,Release[Requirement ID],0))),"",INDEX(Release[Release],MATCH($A17,Release[Requirement ID],0))),"") | L17: 46226 | M17: Created | N17: https://smartship.atlassian.net/browse/DTTP25-41936 | P17: =IFERROR(VALUE(MID($A17,5,4)),0) -> 76 | Q17: NEW-0076
A18: =IF(AND(B18="",C18="",D18="",E18="",F18="",G18="",H18="",J18="",L18="",M18="",N18=""),"",Q18) -> NEW-0077 | B18: Nordics SWE, DEN, NOR, FIN Rollout - Market Configurations in CHAIN1 & CHAIN2 | C18: Config | D18: MVP Rollout | E18: B2CW | F18: NEW | G18: Medium | I18: =IF($A18="","",IFERROR(IF(ISBLANK(INDEX(SprintPlanning[Sprint],MATCH($A18,SprintPlanning[Requirement ID],0))),"To Plan",INDEX(SprintPlanning[Sprint],MATCH($A18,SprintPlanning[Requirement ID],0))),"To Plan")) -> To Plan | J18: 8 | K18: =IFERROR(IF(ISBLANK(INDEX(Release[Release],MATCH($A18,Release[Requirement ID],0))),"",INDEX(Release[Release],MATCH($A18,Release[Requirement ID],0))),"") | L18: 46226 | M18: Created | N18: https://smartship.atlassian.net/browse/DTTP25-37831 | P18: =IFERROR(VALUE(MID($A18,5,4)),0) -> 77 | Q18: NEW-0077
A19: =IF(AND(B19="",C19="",D19="",E19="",F19="",G19="",H19="",J19="",L19="",M19="",N19=""),"",Q19) -> NEW-0078 | B19: Nordics SWE, DEN, NOR, FIN Rollout - Market Configurations in Production | C19: Config | D19: MVP Rollout | E19: B2CW | F19: NEW | G19: Medium | I19: =IF($A19="","",IFERROR(IF(ISBLANK(INDEX(SprintPlanning[Sprint],MATCH($A19,SprintPlanning[Requirement ID],0))),"To Plan",INDEX(SprintPlanning[Sprint],MATCH($A19,SprintPlanning[Requirement ID],0))),"To Plan")) -> To Plan | J19: 8 | K19: =IFERROR(IF(ISBLANK(INDEX(Release[Release],MATCH($A19,Release[Requirement ID],0))),"",INDEX(Release[Release],MATCH($A19,Release[Requirement ID],0))),"") | L19: 46226 | M19: Created | N19: https://smartship.atlassian.net/browse/DTTP25-37831 | P19: =IFERROR(VALUE(MID($A19,5,4)),0) -> 78 | Q19: NEW-0078
A20: =IF(AND(B20="",C20="",D20="",E20="",F20="",G20="",H20="",J20="",L20="",M20="",N20=""),"",Q20) -> NEW-0409 | B20: US Growth - B2CW Payment billing data/ US Release AVS Check - Part 2 (Wiring the new fields to Datatrans in INT007, INT140, INT146) | C20: CR | D20: Growth | E20: B2CW | F20: NEW | G20: High | H20: Q3 2026 | I20: =IF($A20="","",IFERROR(IF(ISBLANK(INDEX(SprintPlanning[Sprint],MATCH($A20,SprintPlanning[Requirement ID],0))),"To Plan",INDEX(SprintPlanning[Sprint],MATCH($A20,SprintPlanning[Requirement ID],0))),"To Plan")) -> Sprint 11 | J20: 13 | K20: =IFERROR(IF(ISBLANK(INDEX(Release[Release],MATCH($A20,Release[Requirement ID],0))),"",INDEX(Release[Release],MATCH($A20,Release[Requirement ID],0))),"") | L20: 46237 | M20: Created | N20: https://smartship.atlassian.net/browse/MDTTPU-15253 | P20: =IFERROR(VALUE(MID($A20,5,4)),0) -> 409 | Q20: NEW-0409
A21: =IF(AND(B21="",C21="",D21="",E21="",F21="",G21="",H21="",J21="",L21="",M21="",N21=""),"",Q21) -> NEW-0410 | B21: US Growth - M4M Payment billing data/ US Release AVS Check (Adding the fields in M4M transaction init) | C21: CR | D21: Growth | E21: B2CW | F21: ON HOLD | G21: High | H21: Q3 2026 | I21: =IF($A21="","",IFERROR(IF(ISBLANK(INDEX(SprintPlanning[Sprint],MATCH($A21,SprintPlanning[Requirement ID],0))),"To Plan",INDEX(SprintPlanning[Sprint],MATCH($A21,SprintPlanning[Requirement ID],0))),"To Plan")) -> Sprint 12 | J21: 8 | K21: =IFERROR(IF(ISBLANK(INDEX(Release[Release],MATCH($A21,Release[Requirement ID],0))),"",INDEX(Release[Release],MATCH($A21,Release[Requirement ID],0))),"") | L21: 46237 | M21: Created | N21: https://smartship.atlassian.net/browse/MDTTPU-15254 | P21: =IFERROR(VALUE(MID($A21,5,4)),0) -> 410 | Q21: NEW-0410
A22: =IF(AND(B22="",C22="",D22="",E22="",F22="",G22="",H22="",J22="",L22="",M22="",N22=""),"",Q22) -> NEW-0001 | B22: Whatsapp Subscription (Phase 1) | C22: New | D22: Backlog | E22: MA | F22: NEW | G22: Medium | H22: Q3 2026 | I22: =IF($A22="","",IFERROR(IF(ISBLANK(INDEX(SprintPlanning[Sprint],MATCH($A22,SprintPlanning[Requirement ID],0))),"To Plan",INDEX(SprintPlanning[Sprint],MATCH($A22,SprintPlanning[Requirement ID],0))),"To Plan")) -> Sprint 12 | J22: 13 | K22: =IFERROR(IF(ISBLANK(INDEX(Release[Release],MATCH($A22,Release[Requirement ID],0))),"",INDEX(Release[Release],MATCH($A22,Release[Requirement ID],0))),"") | L22: 46226 | M22: Created | N22: https://smartship.atlassian.net/browse/DTTP25-36678 | P22: =IFERROR(VALUE(MID($A22,5,4)),0) -> 1 | Q22: NEW-0001
A23: =IF(AND(B23="",C23="",D23="",E23="",F23="",G23="",H23="",J23="",L23="",M23="",N23=""),"",Q23) -> NEW-0003 | B23: Friends and Family INT 157 | C23: New | D23: Backlog | E23: S&S | F23: NEW | G23: Medium | I23: =IF($A23="","",IFERROR(IF(ISBLANK(INDEX(SprintPlanning[Sprint],MATCH($A23,SprintPlanning[Requirement ID],0))),"To Plan",INDEX(SprintPlanning[Sprint],MATCH($A23,SprintPlanning[Requirement ID],0))),"To Plan")) -> Sprint 12 | J23: 13 | K23: =IFERROR(IF(ISBLANK(INDEX(Release[Release],MATCH($A23,Release[Requirement ID],0))),"",INDEX(Release[Release],MATCH($A23,Release[Requirement ID],0))),"") | L23: 46226 | M23: Created | N23: https://smartship.atlassian.net/browse/DTTP25-36959 | P23: =IFERROR(VALUE(MID($A23,5,4)),0) -> 3 | Q23: NEW-0003
A24: =IF(AND(B24="",C24="",D24="",E24="",F24="",G24="",H24="",J24="",L24="",M24="",N24=""),"",Q24) -> NEW-0029 | B24: MYMSC All inc CR remove logic from AEM | C24: CR | D24: MyMSC | E24: B2CW | F24: NEW | G24: Medium | H24: 46235 | I24: =IF($A24="","",IFERROR(IF(ISBLANK(INDEX(SprintPlanning[Sprint],MATCH($A24,SprintPlanning[Requirement ID],0))),"To Plan",INDEX(SprintPlanning[Sprint],MATCH($A24,SprintPlanning[Requirement ID],0))),"To Plan")) -> Sprint 11 | J24: 23 | K24: =IFERROR(IF(ISBLANK(INDEX(Release[Release],MATCH($A24,Release[Requirement ID],0))),"",INDEX(Release[Release],MATCH($A24,Release[Requirement ID],0))),"") | L24: 46226 | M24: Created | N24: https://smartship.atlassian.net/browse/DTTP25-38250 | P24: =IFERROR(VALUE(MID($A24,5,4)),0) -> 29 | Q24: NEW-0029
A25: =IF(AND(B25="",C25="",D25="",E25="",F25="",G25="",H25="",J25="",L25="",M25="",N25=""),"",Q25) -> NEW-0030 | B25: Handling of additional errors INT 139/ INT 140 | C25: CR | D25: MyMSC | E25: B2CW | F25: NEW | G25: Medium | I25: =IF($A25="","",IFERROR(IF(ISBLANK(INDEX(SprintPlanning[Sprint],MATCH($A25,SprintPlanning[Requirement ID],0))),"To Plan",INDEX(SprintPlanning[Sprint],MATCH($A25,SprintPlanning[Requirement ID],0))),"To Plan")) -> Sprint 12 | J25: 8 | K25: =IFERROR(IF(ISBLANK(INDEX(Release[Release],MATCH($A25,Release[Requirement ID],0))),"",INDEX(Release[Release],MATCH($A25,Release[Requirement ID],0))),"") | L25: 46226 | M25: Created | N25: https://smartship.atlassian.net/browse/DTTP25-40357 | P25: =IFERROR(VALUE(MID($A25,5,4)),0) -> 30 | Q25: NEW-0030
A26: =IF(AND(B26="",C26="",D26="",E26="",F26="",G26="",H26="",J26="",L26="",M26="",N26=""),"",Q26) -> NEW-0080 | B26: Hypercare | C26: Tech Task | D26: US | E26: ALL | F26: NEW | G26: High | I26: =IF($A26="","",IFERROR(IF(ISBLANK(INDEX(SprintPlanning[Sprint],MATCH($A26,SprintPlanning[Requirement ID],0))),"To Plan",INDEX(SprintPlanning[Sprint],MATCH($A26,SprintPlanning[Requirement ID],0))),"To Plan")) -> Sprint 12 | K26: =IFERROR(IF(ISBLANK(INDEX(Release[Release],MATCH($A26,Release[Requirement ID],0))),"",INDEX(Release[Release],MATCH($A26,Release[Requirement ID],0))),"") | L26: 46226 | P26: =IFERROR(VALUE(MID($A26,5,4)),0) -> 80 | Q26: NEW-0080
A27: =IF(AND(B27="",C27="",D27="",E27="",F27="",G27="",H27="",J27="",L27="",M27="",N27=""),"",Q27) -> NEW-0085 | B27: PI11-08 [CDP] [INTP-21] Lead Management - Option event creation in CDP | C27: CR | D27: PI11 | E27: MA | F27: NEW | G27: Medium | I27: =IF($A27="","",IFERROR(IF(ISBLANK(INDEX(SprintPlanning[Sprint],MATCH($A27,SprintPlanning[Requirement ID],0))),"To Plan",INDEX(SprintPlanning[Sprint],MATCH($A27,SprintPlanning[Requirement ID],0))),"To Plan")) -> Sprint 12 | J27: 5 | K27: =IFERROR(IF(ISBLANK(INDEX(Release[Release],MATCH($A27,Release[Requirement ID],0))),"",INDEX(Release[Release],MATCH($A27,Release[Requirement ID],0))),"") | L27: 46226 | M27: Created | N27: https://smartship.atlassian.net/browse/DTTP25-41937 | P27: =IFERROR(VALUE(MID($A27,5,4)),0) -> 85 | Q27: NEW-0085
A28: =IF(AND(B28="",C28="",D28="",E28="",F28="",G28="",H28="",J28="",L28="",M28="",N28=""),"",Q28) -> NEW-0086 | B28: PI11-11 [CRM] [EA-1008] DTTP - Lead Management - FCC new outbound sources | C28: CR | D28: PI11 | E28: MA | F28: NEW | G28: Medium | I28: =IF($A28="","",IFERROR(IF(ISBLANK(INDEX(SprintPlanning[Sprint],MATCH($A28,SprintPlanning[Requirement ID],0))),"To Plan",INDEX(SprintPlanning[Sprint],MATCH($A28,SprintPlanning[Requirement ID],0))),"To Plan")) -> Sprint 12 | J28: 8 | K28: =IFERROR(IF(ISBLANK(INDEX(Release[Release],MATCH($A28,Release[Requirement ID],0))),"",INDEX(Release[Release],MATCH($A28,Release[Requirement ID],0))),"") | L28: 46226 | M28: Created | N28: https://smartship.atlassian.net/browse/DTTP25-41939 | P28: =IFERROR(VALUE(MID($A28,5,4)),0) -> 86 | Q28: NEW-0086
A29: =IF(AND(B29="",C29="",D29="",E29="",F29="",G29="",H29="",J29="",L29="",M29="",N29=""),"",Q29) -> NEW-0087 | B29: PI11-12 [CDP/CRM] CRM2-11097 / [INTP-20] Lead Management - IRL Outbound Sources Activation & Form Creation | C29: CR | D29: PI11 | E29: MA | F29: NEW | G29: Medium | I29: =IF($A29="","",IFERROR(IF(ISBLANK(INDEX(SprintPlanning[Sprint],MATCH($A29,SprintPlanning[Requirement ID],0))),"To Plan",INDEX(SprintPlanning[Sprint],MATCH($A29,SprintPlanning[Requirement ID],0))),"To Plan")) -> Sprint 12 | J29: 5 | K29: =IFERROR(IF(ISBLANK(INDEX(Release[Release],MATCH($A29,Release[Requirement ID],0))),"",INDEX(Release[Release],MATCH($A29,Release[Requirement ID],0))),"") | L29: 46226 | M29: Created | N29: https://smartship.atlassian.net/browse/DTTP25-41940 | P29: =IFERROR(VALUE(MID($A29,5,4)),0) -> 87 | Q29: NEW-0087
A30: =IF(AND(B30="",C30="",D30="",E30="",F30="",G30="",H30="",J30="",L30="",M30="",N30=""),"",Q30) -> NEW-0316 | B30: INT139 / INT140 - speciality restaurants CR to handle dining inventory errors | C30: CR | D30: MyMSC | E30: B2CW | F30: NEW | G30: Medium | I30: =IF($A30="","",IFERROR(IF(ISBLANK(INDEX(SprintPlanning[Sprint],MATCH($A30,SprintPlanning[Requirement ID],0))),"To Plan",INDEX(SprintPlanning[Sprint],MATCH($A30,SprintPlanning[Requirement ID],0))),"To Plan")) -> Sprint 12 | J30: 8 | K30: =IFERROR(IF(ISBLANK(INDEX(Release[Release],MATCH($A30,Release[Requirement ID],0))),"",INDEX(Release[Release],MATCH($A30,Release[Requirement ID],0))),"") | L30: 46232 | M30: Created | N30: https://smartship.atlassian.net/browse/DTTP25-40356 | P30: =IFERROR(VALUE(MID($A30,5,4)),0) -> 316 | Q30: NEW-0316
A31: =IF(AND(B31="",C31="",D31="",E31="",F31="",G31="",H31="",J31="",L31="",M31="",N31=""),"",Q31) -> NEW-0066 | B31: PI11-03 [B2C] Flight Enhancement - DTTP25-38915 | C31: CR | D31: PI11 | E31: B2CW | F31: NEW | G31: Medium | I31: =IF($A31="","",IFERROR(IF(ISBLANK(INDEX(SprintPlanning[Sprint],MATCH($A31,SprintPlanning[Requirement ID],0))),"To Plan",INDEX(SprintPlanning[Sprint],MATCH($A31,SprintPlanning[Requirement ID],0))),"To Plan")) -> Sprint 12 | J31: 5 | K31: =IFERROR(IF(ISBLANK(INDEX(Release[Release],MATCH($A31,Release[Requirement ID],0))),"",INDEX(Release[Release],MATCH($A31,Release[Requirement ID],0))),"") | L31: 46226 | M31: Created | N31: https://smartship.atlassian.net/browse/DTTP25-41930 | P31: =IFERROR(VALUE(MID($A31,5,4)),0) -> 66 | Q31: NEW-0066
A32: =IF(AND(B32="",C32="",D32="",E32="",F32="",G32="",H32="",J32="",L32="",M32="",N32=""),"",Q32) -> NEW-0067 | B32: PI11-14 [CRM] [EA-1722] CRM Dependency - Lead Management - Price Description info in CDP | C32: CR | D32: PI11 | E32: MA | F32: NEW | G32: Medium | I32: =IF($A32="","",IFERROR(IF(ISBLANK(INDEX(SprintPlanning[Sprint],MATCH($A32,SprintPlanning[Requirement ID],0))),"To Plan",INDEX(SprintPlanning[Sprint],MATCH($A32,SprintPlanning[Requirement ID],0))),"To Plan")) -> Sprint 12 | J32: 8 | K32: =IFERROR(IF(ISBLANK(INDEX(Release[Release],MATCH($A32,Release[Requirement ID],0))),"",INDEX(Release[Release],MATCH($A32,Release[Requirement ID],0))),"") | L32: 46226 | M32: Created | N32: https://smartship.atlassian.net/browse/DTTP25-41931 | P32: =IFERROR(VALUE(MID($A32,5,4)),0) -> 67 | Q32: NEW-0067
A33: =IF(AND(B33="",C33="",D33="",E33="",F33="",G33="",H33="",J33="",L33="",M33="",N33=""),"",Q33) -> NEW-0002 | B33: Whatsapp Subscription (Phase 2) | C33: CR | D33: Backlog | E33: MA | F33: ON HOLD | G33: Medium | H33: Q4 2026 | I33: =IF($A33="","",IFERROR(IF(ISBLANK(INDEX(SprintPlanning[Sprint],MATCH($A33,SprintPlanning[Requirement ID],0))),"To Plan",INDEX(SprintPlanning[Sprint],MATCH($A33,SprintPlanning[Requirement ID],0))),"To Plan")) -> To Plan | K33: =IFERROR(IF(ISBLANK(INDEX(Release[Release],MATCH($A33,Release[Requirement ID],0))),"",INDEX(Release[Release],MATCH($A33,Release[Requirement ID],0))),"") | L33: 46226 | P33: =IFERROR(VALUE(MID($A33,5,4)),0) -> 2 | Q33: NEW-0002
A34: =IF(AND(B34="",C34="",D34="",E34="",F34="",G34="",H34="",J34="",L34="",M34="",N34=""),"",Q34) -> NEW-0005 | B34: Handling multicabin booking | C34: CR | D34: Growth | E34: B2CW | F34: NEW | G34: Medium | H34: Q4 2026 | I34: =IF($A34="","",IFERROR(IF(ISBLANK(INDEX(SprintPlanning[Sprint],MATCH($A34,SprintPlanning[Requirement ID],0))),"To Plan",INDEX(SprintPlanning[Sprint],MATCH($A34,SprintPlanning[Requirement ID],0))),"To Plan")) -> To Plan | J34: 21 | K34: =IFERROR(IF(ISBLANK(INDEX(Release[Release],MATCH($A34,Release[Requirement ID],0))),"",INDEX(Release[Release],MATCH($A34,Release[Requirement ID],0))),"") | L34: 46226 | P34: =IFERROR(VALUE(MID($A34,5,4)),0) -> 5 | Q34: NEW-0005
A35: =IF(AND(B35="",C35="",D35="",E35="",F35="",G35="",H35="",J35="",L35="",M35="",N35=""),"",Q35) -> NEW-0006 | B35: New UWO Interface (decoupling) | C35: New | D35: Growth | E35: B2CW | F35: NEW | G35: Medium | H35: Q1 2027 | I35: =IF($A35="","",IFERROR(IF(ISBLANK(INDEX(SprintPlanning[Sprint],MATCH($A35,SprintPlanning[Requirement ID],0))),"To Plan",INDEX(SprintPlanning[Sprint],MATCH($A35,SprintPlanning[Requirement ID],0))),"To Plan")) -> To Plan | J35: 3 | K35: =IFERROR(IF(ISBLANK(INDEX(Release[Release],MATCH($A35,Release[Requirement ID],0))),"",INDEX(Release[Release],MATCH($A35,Release[Requirement ID],0))),"") | L35: 46226 | P35: =IFERROR(VALUE(MID($A35,5,4)),0) -> 6 | Q35: NEW-0006
A36: =IF(AND(B36="",C36="",D36="",E36="",F36="",G36="",H36="",J36="",L36="",M36="",N36=""),"",Q36) -> NEW-0007 | B36: Update Hold option (decoupling) | C36: CR | D36: Growth | E36: B2CW | F36: NEW | G36: Medium | H36: Q1 2027 | I36: =IF($A36="","",IFERROR(IF(ISBLANK(INDEX(SprintPlanning[Sprint],MATCH($A36,SprintPlanning[Requirement ID],0))),"To Plan",INDEX(SprintPlanning[Sprint],MATCH($A36,SprintPlanning[Requirement ID],0))),"To Plan")) -> To Plan | J36: 3 | K36: =IFERROR(IF(ISBLANK(INDEX(Release[Release],MATCH($A36,Release[Requirement ID],0))),"",INDEX(Release[Release],MATCH($A36,Release[Requirement ID],0))),"") | L36: 46226 | P36: =IFERROR(VALUE(MID($A36,5,4)),0) -> 7 | Q36: NEW-0007
A37: =IF(AND(B37="",C37="",D37="",E37="",F37="",G37="",H37="",J37="",L37="",M37="",N37=""),"",Q37) -> NEW-0011 | B37: INT 101 - Cabin Selections (Booking Group Management) | C37: CR | D37: Growth | E37: S&S | F37: NEW | G37: Medium | H37: Q4 2026 | I37: =IF($A37="","",IFERROR(IF(ISBLANK(INDEX(SprintPlanning[Sprint],MATCH($A37,SprintPlanning[Requirement ID],0))),"To Plan",INDEX(SprintPlanning[Sprint],MATCH($A37,SprintPlanning[Requirement ID],0))),"To Plan")) -> To Plan | J37: 8 | K37: =IFERROR(IF(ISBLANK(INDEX(Release[Release],MATCH($A37,Release[Requirement ID],0))),"",INDEX(Release[Release],MATCH($A37,Release[Requirement ID],0))),"") | L37: 46226 | M37: Created | N37: https://smartship.atlassian.net/browse/MDTTPU-8135 | P37: =IFERROR(VALUE(MID($A37,5,4)),0) -> 11 | Q37: NEW-0011
A38: =IF(AND(B38="",C38="",D38="",E38="",F38="",G38="",H38="",J38="",L38="",M38="",N38=""),"",Q38) -> NEW-0016 | B38: myMSC Add USA Market Configuration - Chain 1/ Chain 2 | C38: Config | D38: US | E38: B2CW | F38: NEW | G38: Medium | H38: Q3 2026 | I38: =IF($A38="","",IFERROR(IF(ISBLANK(INDEX(SprintPlanning[Sprint],MATCH($A38,SprintPlanning[Requirement ID],0))),"To Plan",INDEX(SprintPlanning[Sprint],MATCH($A38,SprintPlanning[Requirement ID],0))),"To Plan")) -> To Plan | J38: 8 | K38: =IFERROR(IF(ISBLANK(INDEX(Release[Release],MATCH($A38,Release[Requirement ID],0))),"",INDEX(Release[Release],MATCH($A38,Release[Requirement ID],0))),"") | L38: 46226 | M38: Created | N38: https://smartship.atlassian.net/browse/MDTTPU-13662 | P38: =IFERROR(VALUE(MID($A38,5,4)),0) -> 16 | Q38: NEW-0016
A39: =IF(AND(B39="",C39="",D39="",E39="",F39="",G39="",H39="",J39="",L39="",M39="",N39=""),"",Q39) -> NEW-0017 | B39: ARG Payment provider Pagtur | C39: New | D39: MVP Rollout | E39: B2CW | F39: NEW | G39: Medium | H39: Q1 2027 | I39: =IF($A39="","",IFERROR(IF(ISBLANK(INDEX(SprintPlanning[Sprint],MATCH($A39,SprintPlanning[Requirement ID],0))),"To Plan",INDEX(SprintPlanning[Sprint],MATCH($A39,SprintPlanning[Requirement ID],0))),"To Plan")) -> To Plan | J39: 40 | K39: =IFERROR(IF(ISBLANK(INDEX(Release[Release],MATCH($A39,Release[Requirement ID],0))),"",INDEX(Release[Release],MATCH($A39,Release[Requirement ID],0))),"") | L39: 46226 | P39: =IFERROR(VALUE(MID($A39,5,4)),0) -> 17 | Q39: NEW-0017
A40: =IF(AND(B40="",C40="",D40="",E40="",F40="",G40="",H40="",J40="",L40="",M40="",N40=""),"",Q40) -> NEW-0018 | B40: BR Payment providerDireçao | C40: New | D40: MVP Rollout | E40: B2CW | F40: NEW | G40: Medium | H40: Q1 2027 | I40: =IF($A40="","",IFERROR(IF(ISBLANK(INDEX(SprintPlanning[Sprint],MATCH($A40,SprintPlanning[Requirement ID],0))),"To Plan",INDEX(SprintPlanning[Sprint],MATCH($A40,SprintPlanning[Requirement ID],0))),"To Plan")) -> To Plan | J40: 40 | K40: =IFERROR(IF(ISBLANK(INDEX(Release[Release],MATCH($A40,Release[Requirement ID],0))),"",INDEX(Release[Release],MATCH($A40,Release[Requirement ID],0))),"") | L40: 46226 | P40: =IFERROR(VALUE(MID($A40,5,4)),0) -> 18 | Q40: NEW-0018
...

Sheet API Design Planning
A1: Requirement ID | B1: Requirement Name | C1: Stream | D1: Jira Link | E1: Status | F1: Sprint | G1: RAML Required | H1: RAML Delivery Date | I1: Assignee | J1: Priority | K1: Design Status | L1: Design estimate | M1: Handover | N1: Notes
A2: =Backlog!A2 -> NEW-0267 | B2: =IFERROR(IF(ISBLANK(INDEX(Backlog[Requirement Name],MATCH($A2,Backlog[Requirement ID],0))),"",INDEX(Backlog[Requirement Name],MATCH($A2,Backlog[Requirement ID],0))),"") -> Outbound leads - Abandoned Cart - Replacement of Salescycle | C2: =IFERROR(IF(ISBLANK(INDEX(Backlog[Stream],MATCH($A2,Backlog[Requirement ID],0))),"",INDEX(Backlog[Stream],MATCH($A2,Backlog[Requirement ID],0))),"") -> US | D2: =IFERROR(IF(ISBLANK(INDEX(Backlog[Jira Link],MATCH($A2,Backlog[Requirement ID],0))),"",INDEX(Backlog[Jira Link],MATCH($A2,Backlog[Requirement ID],0))),"") | E2: =IFERROR(IF(ISBLANK(INDEX(Backlog[Status],MATCH($A2,Backlog[Requirement ID],0))),"",INDEX(Backlog[Status],MATCH($A2,Backlog[Requirement ID],0))),"") -> ON HOLD | F2: =IFERROR(IF(ISBLANK(INDEX(SprintPlanning[Sprint],MATCH($A2,SprintPlanning[Requirement ID],0))),"",INDEX(SprintPlanning[Sprint],MATCH($A2,SprintPlanning[Requirement ID],0))),"") -> To Plan | J2: =IFERROR(IF(ISBLANK(INDEX(Backlog[Priority],MATCH($A2,Backlog[Requirement ID],0))),"",INDEX(Backlog[Priority],MATCH($A2,Backlog[Requirement ID],0))),"") -> Medium | K2: Pending Solution | L2: =IFERROR(IF(ISBLANK(INDEX(Backlog[HLE],MATCH($A2,Backlog[Requirement ID],0))),"",IF(INDEX(Backlog[HLE],MATCH($A2,Backlog[Requirement ID],0))<=5,0.5,IF(INDEX(Backlog[HLE],MATCH($A2,Backlog[Requirement ID],0))<=8,1,IF(INDEX(Backlog[HLE],MATCH($A2,Backlog[Requirement ID],0))<=13,2,IF(INDEX(Backlog[HLE],MATCH($A2,Backlog[Requirement ID],0))<=20,3,5))))),"")
A3: =Backlog!A3 -> NEW-0057 | B3: =IFERROR(IF(ISBLANK(INDEX(Backlog[Requirement Name],MATCH($A3,Backlog[Requirement ID],0))),"",INDEX(Backlog[Requirement Name],MATCH($A3,Backlog[Requirement ID],0))),"") -> API Prod Configurations - Attentive / Webforms | C3: =IFERROR(IF(ISBLANK(INDEX(Backlog[Stream],MATCH($A3,Backlog[Requirement ID],0))),"",INDEX(Backlog[Stream],MATCH($A3,Backlog[Requirement ID],0))),"") -> US | D3: =IFERROR(IF(ISBLANK(INDEX(Backlog[Jira Link],MATCH($A3,Backlog[Requirement ID],0))),"",INDEX(Backlog[Jira Link],MATCH($A3,Backlog[Requirement ID],0))),"") -> https://smartship.atlassian.net/browse/MDTTPU-14019 | E3: =IFERROR(IF(ISBLANK(INDEX(Backlog[Status],MATCH($A3,Backlog[Requirement ID],0))),"",INDEX(Backlog[Status],MATCH($A3,Backlog[Requirement ID],0))),"") -> IN PROGRESS | F3: =IFERROR(IF(ISBLANK(INDEX(SprintPlanning[Sprint],MATCH($A3,SprintPlanning[Requirement ID],0))),"",INDEX(SprintPlanning[Sprint],MATCH($A3,SprintPlanning[Requirement ID],0))),"") -> Sprint 10 | J3: =IFERROR(IF(ISBLANK(INDEX(Backlog[Priority],MATCH($A3,Backlog[Requirement ID],0))),"",INDEX(Backlog[Priority],MATCH($A3,Backlog[Requirement ID],0))),"") -> High | K3: No Design Required | L3: =IFERROR(IF(ISBLANK(INDEX(Backlog[HLE],MATCH($A3,Backlog[Requirement ID],0))),"",IF(INDEX(Backlog[HLE],MATCH($A3,Backlog[Requirement ID],0))<=5,0.5,IF(INDEX(Backlog[HLE],MATCH($A3,Backlog[Requirement ID],0))<=8,1,IF(INDEX(Backlog[HLE],MATCH($A3,Backlog[Requirement ID],0))<=13,2,IF(INDEX(Backlog[HLE],MATCH($A3,Backlog[Requirement ID],0))<=20,3,5))))),"") -> 1
A4: =Backlog!A4 -> NEW-0058 | B4: =IFERROR(IF(ISBLANK(INDEX(Backlog[Requirement Name],MATCH($A4,Backlog[Requirement ID],0))),"",INDEX(Backlog[Requirement Name],MATCH($A4,Backlog[Requirement ID],0))),"") -> CR - Attentive Error Scenarios INT 175 | C4: =IFERROR(IF(ISBLANK(INDEX(Backlog[Stream],MATCH($A4,Backlog[Requirement ID],0))),"",INDEX(Backlog[Stream],MATCH($A4,Backlog[Requirement ID],0))),"") -> US | D4: =IFERROR(IF(ISBLANK(INDEX(Backlog[Jira Link],MATCH($A4,Backlog[Requirement ID],0))),"",INDEX(Backlog[Jira Link],MATCH($A4,Backlog[Requirement ID],0))),"") -> https://smartship.atlassian.net/browse/MDTTPU-13413 | E4: =IFERROR(IF(ISBLANK(INDEX(Backlog[Status],MATCH($A4,Backlog[Requirement ID],0))),"",INDEX(Backlog[Status],MATCH($A4,Backlog[Requirement ID],0))),"") -> IN PROGRESS | F4: =IFERROR(IF(ISBLANK(INDEX(SprintPlanning[Sprint],MATCH($A4,SprintPlanning[Requirement ID],0))),"",INDEX(SprintPlanning[Sprint],MATCH($A4,SprintPlanning[Requirement ID],0))),"") -> Sprint 10 | J4: =IFERROR(IF(ISBLANK(INDEX(Backlog[Priority],MATCH($A4,Backlog[Requirement ID],0))),"",INDEX(Backlog[Priority],MATCH($A4,Backlog[Requirement ID],0))),"") -> Medium | K4: Ready for Development | L4: =IFERROR(IF(ISBLANK(INDEX(Backlog[HLE],MATCH($A4,Backlog[Requirement ID],0))),"",IF(INDEX(Backlog[HLE],MATCH($A4,Backlog[Requirement ID],0))<=5,0.5,IF(INDEX(Backlog[HLE],MATCH($A4,Backlog[Requirement ID],0))<=8,1,IF(INDEX(Backlog[HLE],MATCH($A4,Backlog[Requirement ID],0))<=13,2,IF(INDEX(Backlog[HLE],MATCH($A4,Backlog[Requirement ID],0))<=20,3,5))))),"") -> 0.5
A5: =Backlog!A5 -> NEW-0060 | B5: =IFERROR(IF(ISBLANK(INDEX(Backlog[Requirement Name],MATCH($A5,Backlog[Requirement ID],0))),"",INDEX(Backlog[Requirement Name],MATCH($A5,Backlog[Requirement ID],0))),"") -> US Configuration myMSC - Production | C5: =IFERROR(IF(ISBLANK(INDEX(Backlog[Stream],MATCH($A5,Backlog[Requirement ID],0))),"",INDEX(Backlog[Stream],MATCH($A5,Backlog[Requirement ID],0))),"") -> US | D5: =IFERROR(IF(ISBLANK(INDEX(Backlog[Jira Link],MATCH($A5,Backlog[Requirement ID],0))),"",INDEX(Backlog[Jira Link],MATCH($A5,Backlog[Requirement ID],0))),"") -> https://smartship.atlassian.net/browse/MDTTPU-14018 | E5: =IFERROR(IF(ISBLANK(INDEX(Backlog[Status],MATCH($A5,Backlog[Requirement ID],0))),"",INDEX(Backlog[Status],MATCH($A5,Backlog[Requirement ID],0))),"") -> IN PROGRESS | F5: =IFERROR(IF(ISBLANK(INDEX(SprintPlanning[Sprint],MATCH($A5,SprintPlanning[Requirement ID],0))),"",INDEX(SprintPlanning[Sprint],MATCH($A5,SprintPlanning[Requirement ID],0))),"") -> Sprint 10 | J5: =IFERROR(IF(ISBLANK(INDEX(Backlog[Priority],MATCH($A5,Backlog[Requirement ID],0))),"",INDEX(Backlog[Priority],MATCH($A5,Backlog[Requirement ID],0))),"") -> High | K5: No Design Required | L5: =IFERROR(IF(ISBLANK(INDEX(Backlog[HLE],MATCH($A5,Backlog[Requirement ID],0))),"",IF(INDEX(Backlog[HLE],MATCH($A5,Backlog[Requirement ID],0))<=5,0.5,IF(INDEX(Backlog[HLE],MATCH($A5,Backlog[Requirement ID],0))<=8,1,IF(INDEX(Backlog[HLE],MATCH($A5,Backlog[Requirement ID],0))<=13,2,IF(INDEX(Backlog[HLE],MATCH($A5,Backlog[Requirement ID],0))<=20,3,5))))),"") -> 1
A6: =Backlog!A6 -> NEW-0061 | B6: =IFERROR(IF(ISBLANK(INDEX(Backlog[Requirement Name],MATCH($A6,Backlog[Requirement ID],0))),"",INDEX(Backlog[Requirement Name],MATCH($A6,Backlog[Requirement ID],0))),"") -> Load Test + Performance Enhancements - Part 1 | C6: =IFERROR(IF(ISBLANK(INDEX(Backlog[Stream],MATCH($A6,Backlog[Requirement ID],0))),"",INDEX(Backlog[Stream],MATCH($A6,Backlog[Requirement ID],0))),"") -> US | D6: =IFERROR(IF(ISBLANK(INDEX(Backlog[Jira Link],MATCH($A6,Backlog[Requirement ID],0))),"",INDEX(Backlog[Jira Link],MATCH($A6,Backlog[Requirement ID],0))),"") -> https://smartship.atlassian.net/browse/MDTTPU-15260 | E6: =IFERROR(IF(ISBLANK(INDEX(Backlog[Status],MATCH($A6,Backlog[Requirement ID],0))),"",INDEX(Backlog[Status],MATCH($A6,Backlog[Requirement ID],0))),"") -> IN PROGRESS | F6: =IFERROR(IF(ISBLANK(INDEX(SprintPlanning[Sprint],MATCH($A6,SprintPlanning[Requirement ID],0))),"",INDEX(SprintPlanning[Sprint],MATCH($A6,SprintPlanning[Requirement ID],0))),"") -> Sprint 10 | J6: =IFERROR(IF(ISBLANK(INDEX(Backlog[Priority],MATCH($A6,Backlog[Requirement ID],0))),"",INDEX(Backlog[Priority],MATCH($A6,Backlog[Requirement ID],0))),"") -> High | K6: No Design Required | L6: =IFERROR(IF(ISBLANK(INDEX(Backlog[HLE],MATCH($A6,Backlog[Requirement ID],0))),"",IF(INDEX(Backlog[HLE],MATCH($A6,Backlog[Requirement ID],0))<=5,0.5,IF(INDEX(Backlog[HLE],MATCH($A6,Backlog[Requirement ID],0))<=8,1,IF(INDEX(Backlog[HLE],MATCH($A6,Backlog[Requirement ID],0))<=13,2,IF(INDEX(Backlog[HLE],MATCH($A6,Backlog[Requirement ID],0))<=20,3,5))))),"") -> 5
A7: =Backlog!A7 -> NEW-0071 | B7: =IFERROR(IF(ISBLANK(INDEX(Backlog[Requirement Name],MATCH($A7,Backlog[Requirement ID],0))),"",INDEX(Backlog[Requirement Name],MATCH($A7,Backlog[Requirement ID],0))),"") -> E2E Ticket Support - FAT and Canary Tests | C7: =IFERROR(IF(ISBLANK(INDEX(Backlog[Stream],MATCH($A7,Backlog[Requirement ID],0))),"",INDEX(Backlog[Stream],MATCH($A7,Backlog[Requirement ID],0))),"") -> US | D7: =IFERROR(IF(ISBLANK(INDEX(Backlog[Jira Link],MATCH($A7,Backlog[Requirement ID],0))),"",INDEX(Backlog[Jira Link],MATCH($A7,Backlog[Requirement ID],0))),"") -> https://smartship.atlassian.net/browse/DTTP25-41779 | E7: =IFERROR(IF(ISBLANK(INDEX(Backlog[Status],MATCH($A7,Backlog[Requirement ID],0))),"",INDEX(Backlog[Status],MATCH($A7,Backlog[Requirement ID],0))),"") -> IN PROGRESS | F7: =IFERROR(IF(ISBLANK(INDEX(SprintPlanning[Sprint],MATCH($A7,SprintPlanning[Requirement ID],0))),"",INDEX(SprintPlanning[Sprint],MATCH($A7,SprintPlanning[Requirement ID],0))),"") -> Sprint 10 | J7: =IFERROR(IF(ISBLANK(INDEX(Backlog[Priority],MATCH($A7,Backlog[Requirement ID],0))),"",INDEX(Backlog[Priority],MATCH($A7,Backlog[Requirement ID],0))),"") -> High | K7: No Design Required | L7: =IFERROR(IF(ISBLANK(INDEX(Backlog[HLE],MATCH($A7,Backlog[Requirement ID],0))),"",IF(INDEX(Backlog[HLE],MATCH($A7,Backlog[Requirement ID],0))<=5,0.5,IF(INDEX(Backlog[HLE],MATCH($A7,Backlog[Requirement ID],0))<=8,1,IF(INDEX(Backlog[HLE],MATCH($A7,Backlog[Requirement ID],0))<=13,2,IF(INDEX(Backlog[HLE],MATCH($A7,Backlog[Requirement ID],0))<=20,3,5))))),"") -> 2
A8: =Backlog!A8 -> NEW-0275 | B8: =IFERROR(IF(ISBLANK(INDEX(Backlog[Requirement Name],MATCH($A8,Backlog[Requirement ID],0))),"",INDEX(Backlog[Requirement Name],MATCH($A8,Backlog[Requirement ID],0))),"") -> [EINT] [Tech Task] INT172 INT174 - Attentive Error Scenarios | C8: =IFERROR(IF(ISBLANK(INDEX(Backlog[Stream],MATCH($A8,Backlog[Requirement ID],0))),"",INDEX(Backlog[Stream],MATCH($A8,Backlog[Requirement ID],0))),"") -> US | D8: =IFERROR(IF(ISBLANK(INDEX(Backlog[Jira Link],MATCH($A8,Backlog[Requirement ID],0))),"",INDEX(Backlog[Jira Link],MATCH($A8,Backlog[Requirement ID],0))),"") -> https://smartship.atlassian.net/browse/MDTTPU-13796 | E8: =IFERROR(IF(ISBLANK(INDEX(Backlog[Status],MATCH($A8,Backlog[Requirement ID],0))),"",INDEX(Backlog[Status],MATCH($A8,Backlog[Requirement ID],0))),"") -> IN PROGRESS | F8: =IFERROR(IF(ISBLANK(INDEX(SprintPlanning[Sprint],MATCH($A8,SprintPlanning[Requirement ID],0))),"",INDEX(SprintPlanning[Sprint],MATCH($A8,SprintPlanning[Requirement ID],0))),"") -> Sprint 10 | J8: =IFERROR(IF(ISBLANK(INDEX(Backlog[Priority],MATCH($A8,Backlog[Requirement ID],0))),"",INDEX(Backlog[Priority],MATCH($A8,Backlog[Requirement ID],0))),"") -> Medium | K8: Ready for Development | L8: =IFERROR(IF(ISBLANK(INDEX(Backlog[HLE],MATCH($A8,Backlog[Requirement ID],0))),"",IF(INDEX(Backlog[HLE],MATCH($A8,Backlog[Requirement ID],0))<=5,0.5,IF(INDEX(Backlog[HLE],MATCH($A8,Backlog[Requirement ID],0))<=8,1,IF(INDEX(Backlog[HLE],MATCH($A8,Backlog[Requirement ID],0))<=13,2,IF(INDEX(Backlog[HLE],MATCH($A8,Backlog[Requirement ID],0))<=20,3,5))))),"") -> 0.5 | M8: Yes
A9: =Backlog!A9 -> NEW-0368 | B9: =IFERROR(IF(ISBLANK(INDEX(Backlog[Requirement Name],MATCH($A9,Backlog[Requirement ID],0))),"",INDEX(Backlog[Requirement Name],MATCH($A9,Backlog[Requirement ID],0))),"") -> MyMSC US | [INT112][INT137][INT140][INT146][INT153][INT154][INT188] Add per-country/language MyMSC campaign config check to skip optional marketing automation calls | C9: =IFERROR(IF(ISBLANK(INDEX(Backlog[Stream],MATCH($A9,Backlog[Requirement ID],0))),"",INDEX(Backlog[Stream],MATCH($A9,Backlog[Requirement ID],0))),"") -> Growth | D9: =IFERROR(IF(ISBLANK(INDEX(Backlog[Jira Link],MATCH($A9,Backlog[Requirement ID],0))),"",INDEX(Backlog[Jira Link],MATCH($A9,Backlog[Requirement ID],0))),"") -> https://smartship.atlassian.net/browse/MDTTPU-14929 | E9: =IFERROR(IF(ISBLANK(INDEX(Backlog[Status],MATCH($A9,Backlog[Requirement ID],0))),"",INDEX(Backlog[Status],MATCH($A9,Backlog[Requirement ID],0))),"") -> IN PROGRESS | F9: =IFERROR(IF(ISBLANK(INDEX(SprintPlanning[Sprint],MATCH($A9,SprintPlanning[Requirement ID],0))),"",INDEX(SprintPlanning[Sprint],MATCH($A9,SprintPlanning[Requirement ID],0))),"") -> Sprint 10 | J9: =IFERROR(IF(ISBLANK(INDEX(Backlog[Priority],MATCH($A9,Backlog[Requirement ID],0))),"",INDEX(Backlog[Priority],MATCH($A9,Backlog[Requirement ID],0))),"") -> High | K9: Ready for Development | L9: =IFERROR(IF(ISBLANK(INDEX(Backlog[HLE],MATCH($A9,Backlog[Requirement ID],0))),"",IF(INDEX(Backlog[HLE],MATCH($A9,Backlog[Requirement ID],0))<=5,0.5,IF(INDEX(Backlog[HLE],MATCH($A9,Backlog[Requirement ID],0))<=8,1,IF(INDEX(Backlog[HLE],MATCH($A9,Backlog[Requirement ID],0))<=13,2,IF(INDEX(Backlog[HLE],MATCH($A9,Backlog[Requirement ID],0))<=20,3,5))))),"") -> 1 | M9: Yes
A10: =Backlog!A10 -> NEW-0389 | B10: =IFERROR(IF(ISBLANK(INDEX(Backlog[Requirement Name],MATCH($A10,Backlog[Requirement ID],0))),"",INDEX(Backlog[Requirement Name],MATCH($A10,Backlog[Requirement ID],0))),"") -> [DTTP] Implementation of Online Post-Cruise Complaint Form – Salesforce Integration_EA | C10: =IFERROR(IF(ISBLANK(INDEX(Backlog[Stream],MATCH($A10,Backlog[Requirement ID],0))),"",INDEX(Backlog[Stream],MATCH($A10,Backlog[Requirement ID],0))),"") -> PI10 | D10: =IFERROR(IF(ISBLANK(INDEX(Backlog[Jira Link],MATCH($A10,Backlog[Requirement ID],0))),"",INDEX(Backlog[Jira Link],MATCH($A10,Backlog[Requirement ID],0))),"") -> https://smartship.atlassian.net/browse/DTTP25-40322 | E10: =IFERROR(IF(ISBLANK(INDEX(Backlog[Status],MATCH($A10,Backlog[Requirement ID],0))),"",INDEX(Backlog[Status],MATCH($A10,Backlog[Requirement ID],0))),"") -> IN PROGRESS | F10: =IFERROR(IF(ISBLANK(INDEX(SprintPlanning[Sprint],MATCH($A10,SprintPlanning[Requirement ID],0))),"",INDEX(SprintPlanning[Sprint],MATCH($A10,SprintPlanning[Requirement ID],0))),"") -> Sprint 10 | J10: =IFERROR(IF(ISBLANK(INDEX(Backlog[Priority],MATCH($A10,Backlog[Requirement ID],0))),"",INDEX(Backlog[Priority],MATCH($A10,Backlog[Requirement ID],0))),"") -> Medium | K10: Ready for Development | L10: =IFERROR(IF(ISBLANK(INDEX(Backlog[HLE],MATCH($A10,Backlog[Requirement ID],0))),"",IF(INDEX(Backlog[HLE],MATCH($A10,Backlog[Requirement ID],0))<=5,0.5,IF(INDEX(Backlog[HLE],MATCH($A10,Backlog[Requirement ID],0))<=8,1,IF(INDEX(Backlog[HLE],MATCH($A10,Backlog[Requirement ID],0))<=13,2,IF(INDEX(Backlog[HLE],MATCH($A10,Backlog[Requirement ID],0))<=20,3,5))))),"") -> 1 | M10: Yes
A11: =Backlog!A11 -> NEW-0408 | B11: =IFERROR(IF(ISBLANK(INDEX(Backlog[Requirement Name],MATCH($A11,Backlog[Requirement ID],0))),"",INDEX(Backlog[Requirement Name],MATCH($A11,Backlog[Requirement ID],0))),"") -> US Growth - B2CW Payment billing data/ US Release ACS Check - Part 1 (Adding the new fields to INT007, INT140, INT146) | C11: =IFERROR(IF(ISBLANK(INDEX(Backlog[Stream],MATCH($A11,Backlog[Requirement ID],0))),"",INDEX(Backlog[Stream],MATCH($A11,Backlog[Requirement ID],0))),"") -> Growth | D11: =IFERROR(IF(ISBLANK(INDEX(Backlog[Jira Link],MATCH($A11,Backlog[Requirement ID],0))),"",INDEX(Backlog[Jira Link],MATCH($A11,Backlog[Requirement ID],0))),"") -> https://smartship.atlassian.net/browse/MDTTPU-15252 | E11: =IFERROR(IF(ISBLANK(INDEX(Backlog[Status],MATCH($A11,Backlog[Requirement ID],0))),"",INDEX(Backlog[Status],MATCH($A11,Backlog[Requirement ID],0))),"") -> NEW | F11: =IFERROR(IF(ISBLANK(INDEX(SprintPlanning[Sprint],MATCH($A11,SprintPlanning[Requirement ID],0))),"",INDEX(SprintPlanning[Sprint],MATCH($A11,SprintPlanning[Requirement ID],0))),"") -> Sprint 10 | J11: =IFERROR(IF(ISBLANK(INDEX(Backlog[Priority],MATCH($A11,Backlog[Requirement ID],0))),"",INDEX(Backlog[Priority],MATCH($A11,Backlog[Requirement ID],0))),"") -> High | K11: Ready for Development | L11: =IFERROR(IF(ISBLANK(INDEX(Backlog[HLE],MATCH($A11,Backlog[Requirement ID],0))),"",IF(INDEX(Backlog[HLE],MATCH($A11,Backlog[Requirement ID],0))<=5,0.5,IF(INDEX(Backlog[HLE],MATCH($A11,Backlog[Requirement ID],0))<=8,1,IF(INDEX(Backlog[HLE],MATCH($A11,Backlog[Requirement ID],0))<=13,2,IF(INDEX(Backlog[HLE],MATCH($A11,Backlog[Requirement ID],0))<=20,3,5))))),"") -> 0.5 | M11: Yes
A12: =Backlog!A12 -> NEW-0411 | B12: =IFERROR(IF(ISBLANK(INDEX(Backlog[Requirement Name],MATCH($A12,Backlog[Requirement ID],0))),"",INDEX(Backlog[Requirement Name],MATCH($A12,Backlog[Requirement ID],0))),"") -> Load Test Perf - Support & Analysis | C12: =IFERROR(IF(ISBLANK(INDEX(Backlog[Stream],MATCH($A12,Backlog[Requirement ID],0))),"",INDEX(Backlog[Stream],MATCH($A12,Backlog[Requirement ID],0))),"") -> US | D12: =IFERROR(IF(ISBLANK(INDEX(Backlog[Jira Link],MATCH($A12,Backlog[Requirement ID],0))),"",INDEX(Backlog[Jira Link],MATCH($A12,Backlog[Requirement ID],0))),"") -> https://smartship.atlassian.net/browse/MDTTPU-15252 | E12: =IFERROR(IF(ISBLANK(INDEX(Backlog[Status],MATCH($A12,Backlog[Requirement ID],0))),"",INDEX(Backlog[Status],MATCH($A12,Backlog[Requirement ID],0))),"") -> IN PROGRESS | F12: =IFERROR(IF(ISBLANK(INDEX(SprintPlanning[Sprint],MATCH($A12,SprintPlanning[Requirement ID],0))),"",INDEX(SprintPlanning[Sprint],MATCH($A12,SprintPlanning[Requirement ID],0))),"") -> Sprint 10 | J12: =IFERROR(IF(ISBLANK(INDEX(Backlog[Priority],MATCH($A12,Backlog[Requirement ID],0))),"",INDEX(Backlog[Priority],MATCH($A12,Backlog[Requirement ID],0))),"") -> High | K12: No Design Required | L12: =IFERROR(IF(ISBLANK(INDEX(Backlog[HLE],MATCH($A12,Backlog[Requirement ID],0))),"",IF(INDEX(Backlog[HLE],MATCH($A12,Backlog[Requirement ID],0))<=5,0.5,IF(INDEX(Backlog[HLE],MATCH($A12,Backlog[Requirement ID],0))<=8,1,IF(INDEX(Backlog[HLE],MATCH($A12,Backlog[Requirement ID],0))<=13,2,IF(INDEX(Backlog[HLE],MATCH($A12,Backlog[Requirement ID],0))<=20,3,5))))),"") -> 5
A13: =Backlog!A13 -> NEW-0412 | B13: =IFERROR(IF(ISBLANK(INDEX(Backlog[Requirement Name],MATCH($A13,Backlog[Requirement ID],0))),"",INDEX(Backlog[Requirement Name],MATCH($A13,Backlog[Requirement ID],0))),"") -> US 0.1 Release Preparation - Aug 24 | C13: =IFERROR(IF(ISBLANK(INDEX(Backlog[Stream],MATCH($A13,Backlog[Requirement ID],0))),"",INDEX(Backlog[Stream],MATCH($A13,Backlog[Requirement ID],0))),"") -> Cross | D13: =IFERROR(IF(ISBLANK(INDEX(Backlog[Jira Link],MATCH($A13,Backlog[Requirement ID],0))),"",INDEX(Backlog[Jira Link],MATCH($A13,Backlog[Requirement ID],0))),"") -> https://smartship.atlassian.net/browse/MDTTPU-15262 | E13: =IFERROR(IF(ISBLANK(INDEX(Backlog[Status],MATCH($A13,Backlog[Requirement ID],0))),"",INDEX(Backlog[Status],MATCH($A13,Backlog[Requirement ID],0))),"") -> IN PROGRESS | F13: =IFERROR(IF(ISBLANK(INDEX(SprintPlanning[Sprint],MATCH($A13,SprintPlanning[Requirement ID],0))),"",INDEX(SprintPlanning[Sprint],MATCH($A13,SprintPlanning[Requirement ID],0))),"") -> Sprint 10 | I13: Luke | J13: =IFERROR(IF(ISBLANK(INDEX(Backlog[Priority],MATCH($A13,Backlog[Requirement ID],0))),"",INDEX(Backlog[Priority],MATCH($A13,Backlog[Requirement ID],0))),"") -> High | K13: Pending Design | L13: =IFERROR(IF(ISBLANK(INDEX(Backlog[HLE],MATCH($A13,Backlog[Requirement ID],0))),"",IF(INDEX(Backlog[HLE],MATCH($A13,Backlog[Requirement ID],0))<=5,0.5,IF(INDEX(Backlog[HLE],MATCH($A13,Backlog[Requirement ID],0))<=8,1,IF(INDEX(Backlog[HLE],MATCH($A13,Backlog[Requirement ID],0))<=13,2,IF(INDEX(Backlog[HLE],MATCH($A13,Backlog[Requirement ID],0))<=20,3,5))))),"") -> 2 | N13: merges required post prod release
A14: =Backlog!A14 -> NEW-0064 | B14: =IFERROR(IF(ISBLANK(INDEX(Backlog[Requirement Name],MATCH($A14,Backlog[Requirement ID],0))),"",INDEX(Backlog[Requirement Name],MATCH($A14,Backlog[Requirement ID],0))),"") -> ZAF Rollout - Market Configurations in CHAIN1 & CHAIN2 and PROD | C14: =IFERROR(IF(ISBLANK(INDEX(Backlog[Stream],MATCH($A14,Backlog[Requirement ID],0))),"",INDEX(Backlog[Stream],MATCH($A14,Backlog[Requirement ID],0))),"") -> MVP Rollout | D14: =IFERROR(IF(ISBLANK(INDEX(Backlog[Jira Link],MATCH($A14,Backlog[Requirement ID],0))),"",INDEX(Backlog[Jira Link],MATCH($A14,Backlog[Requirement ID],0))),"") -> https://smartship.atlassian.net/browse/DTTP25-41351 | E14: =IFERROR(IF(ISBLANK(INDEX(Backlog[Status],MATCH($A14,Backlog[Requirement ID],0))),"",INDEX(Backlog[Status],MATCH($A14,Backlog[Requirement ID],0))),"") -> NEW | F14: =IFERROR(IF(ISBLANK(INDEX(SprintPlanning[Sprint],MATCH($A14,SprintPlanning[Requirement ID],0))),"",INDEX(SprintPlanning[Sprint],MATCH($A14,SprintPlanning[Requirement ID],0))),"") -> Sprint 11 | G14: No | J14: =IFERROR(IF(ISBLANK(INDEX(Backlog[Priority],MATCH($A14,Backlog[Requirement ID],0))),"",INDEX(Backlog[Priority],MATCH($A14,Backlog[Requirement ID],0))),"") -> Medium | K14: No Design Required | L14: =IFERROR(IF(ISBLANK(INDEX(Backlog[HLE],MATCH($A14,Backlog[Requirement ID],0))),"",IF(INDEX(Backlog[HLE],MATCH($A14,Backlog[Requirement ID],0))<=5,0.5,IF(INDEX(Backlog[HLE],MATCH($A14,Backlog[Requirement ID],0))<=8,1,IF(INDEX(Backlog[HLE],MATCH($A14,Backlog[Requirement ID],0))<=13,2,IF(INDEX(Backlog[HLE],MATCH($A14,Backlog[Requirement ID],0))<=20,3,5))))),"") -> 1
A15: =Backlog!A15 -> NEW-0065 | B15: =IFERROR(IF(ISBLANK(INDEX(Backlog[Requirement Name],MATCH($A15,Backlog[Requirement ID],0))),"",INDEX(Backlog[Requirement Name],MATCH($A15,Backlog[Requirement ID],0))),"") -> ZAFRollout - Market Configurations in Production | C15: =IFERROR(IF(ISBLANK(INDEX(Backlog[Stream],MATCH($A15,Backlog[Requirement ID],0))),"",INDEX(Backlog[Stream],MATCH($A15,Backlog[Requirement ID],0))),"") -> MVP Rollout | D15: =IFERROR(IF(ISBLANK(INDEX(Backlog[Jira Link],MATCH($A15,Backlog[Requirement ID],0))),"",INDEX(Backlog[Jira Link],MATCH($A15,Backlog[Requirement ID],0))),"") -> https://smartship.atlassian.net/browse/DTTP25-41351 | E15: =IFERROR(IF(ISBLANK(INDEX(Backlog[Status],MATCH($A15,Backlog[Requirement ID],0))),"",INDEX(Backlog[Status],MATCH($A15,Backlog[Requirement ID],0))),"") -> NA | F15: =IFERROR(IF(ISBLANK(INDEX(SprintPlanning[Sprint],MATCH($A15,SprintPlanning[Requirement ID],0))),"",INDEX(SprintPlanning[Sprint],MATCH($A15,SprintPlanning[Requirement ID],0))),"") -> To Plan | G15: No | J15: =IFERROR(IF(ISBLANK(INDEX(Backlog[Priority],MATCH($A15,Backlog[Requirement ID],0))),"",INDEX(Backlog[Priority],MATCH($A15,Backlog[Requirement ID],0))),"") -> Medium | K15: No Design Required | L15: =IFERROR(IF(ISBLANK(INDEX(Backlog[HLE],MATCH($A15,Backlog[Requirement ID],0))),"",IF(INDEX(Backlog[HLE],MATCH($A15,Backlog[Requirement ID],0))<=5,0.5,IF(INDEX(Backlog[HLE],MATCH($A15,Backlog[Requirement ID],0))<=8,1,IF(INDEX(Backlog[HLE],MATCH($A15,Backlog[Requirement ID],0))<=13,2,IF(INDEX(Backlog[HLE],MATCH($A15,Backlog[Requirement ID],0))<=20,3,5))))),"") -> 1
